5:return {{["x"] = 1, ["param2"] = 1, ["y"] = 0, ["param1"] = 14, ["z"] = 2, ["name"] = "stairs:stair_outer_steelblock"}, {["x"] = 1, ["param2"] = 1, ["y"] = 0, ["param1"] = 30, ["z"] = 3, ["name"] = "stairs:stair_steelblock"}, {["x"] = 1, ["param2"] = 1, ["y"] = 0, ["param1"] = 46, ["z"] = 4, ["name"] = "stairs:stair_steelblock"}, {["x"] = 1, ["param2"] = 1, ["y"] = 0, ["param1"] = 62, ["z"] = 5, ["name"] = "stairs:stair_steelblock"}, {["x"] = 1, ["param2"] = 1, ["y"] = 0, ["param1"] = 78, ["z"] = 6, ["name"] = "stairs:stair_steelblock"}, {["x"] = 1, ["param2"] = 1, ["y"] = 0, ["param1"] = 78, ["z"] = 7, ["name"] = "stairs:stair_steelblock"}, {["x"] = 1, ["param2"] = 1, ["y"] = 0, ["param1"] = 78, ["z"] = 8, ["name"] = "stairs:stair_steelblock"}, {["x"] = 1, ["param2"] = 1, ["y"] = 0, ["param1"] = 62, ["z"] = 9, ["name"] = "stairs:stair_steelblock"}, {["x"] = 1, ["param2"] = 1, ["y"] = 0, ["param1"] = 46, ["z"] = 10, ["name"] = "stairs:stair_steelblock"}, {["x"] = 1, ["param2"] = 1, ["y"] = 0, ["param1"] = 62, ["z"] = 11, ["name"] = "stairs:stair_steelblock"}, {["x"] = 1, ["param2"] = 1, ["y"] = 0, ["param1"] = 78, ["z"] = 12, ["name"] = "stairs:stair_steelblock"}, {["x"] = 1, ["param2"] = 1, ["y"] = 0, ["param1"] = 78, ["z"] = 13, ["name"] = "stairs:stair_steelblock"}, {["x"] = 1, ["param2"] = 1, ["y"] = 0, ["param1"] = 62, ["z"] = 14, ["name"] = "stairs:stair_steelblock"}, {["x"] = 1, ["param2"] = 1, ["y"] = 0, ["param1"] = 46, ["z"] = 15, ["name"] = "stairs:stair_steelblock"}, {["x"] = 1, ["param2"] = 1, ["y"] = 0, ["param1"] = 30, ["z"] = 16, ["name"] = "stairs:stair_steelblock"}, {["x"] = 1, ["param2"] = 1, ["y"] = 0, ["param1"] = 30, ["z"] = 17, ["name"] = "stairs:stair_steelblock"}, {["x"] = 1, ["param2"] = 1, ["y"] = 0, ["param1"] = 46, ["z"] = 18, ["name"] = "stairs:stair_steelblock"}, {["x"] = 1, ["param2"] = 1, ["y"] = 0, ["param1"] = 62, ["z"] = 19, ["name"] = "stairs:stair_steelblock"}, {["x"] = 1, ["param2"] = 1, ["y"] = 0, ["param1"] = 78, ["z"] = 20, ["name"] = "stairs:stair_steelblock"}, {["x"] = 1, ["param2"] = 1, ["y"] = 0, ["param1"] = 78, ["z"] = 21, ["name"] = "stairs:stair_steelblock"}, {["x"] = 1, ["param2"] = 1, ["y"] = 0, ["param1"] = 78, ["z"] = 22, ["name"] = "stairs:stair_steelblock"}, {["x"] = 1, ["param2"] = 1, ["y"] = 0, ["param1"] = 62, ["z"] = 23, ["name"] = "stairs:stair_steelblock"}, {["x"] = 1, ["param2"] = 1, ["y"] = 0, ["param1"] = 46, ["z"] = 24, ["name"] = "stairs:stair_steelblock"}, {["x"] = 1, ["param2"] = 1, ["y"] = 0, ["param1"] = 62, ["z"] = 25, ["name"] = "stairs:stair_steelblock"}, {["x"] = 1, ["param2"] = 1, ["y"] = 0, ["param1"] = 78, ["z"] = 26, ["name"] = "stairs:stair_steelblock"}, {["x"] = 1, ["param2"] = 1, ["y"] = 0, ["param1"] = 78, ["z"] = 27, ["name"] = "stairs:stair_steelblock"}, {["x"] = 1, ["param2"] = 1, ["y"] = 0, ["param1"] = 62, ["z"] = 28, ["name"] = "stairs:stair_steelblock"}, {["x"] = 1, ["param2"] = 1, ["y"] = 0, ["param1"] = 46, ["z"] = 29, ["name"] = "stairs:stair_steelblock"}, {["x"] = 1, ["param2"] = 1, ["y"] = 0, ["param1"] = 46, ["z"] = 30, ["name"] = "stairs:stair_steelblock"}, {["x"] = 1, ["param2"] = 1, ["y"] = 0, ["param1"] = 62, ["z"] = 31, ["name"] = "stairs:stair_steelblock"}, {["x"] = 1, ["param2"] = 1, ["y"] = 0, ["param1"] = 78, ["z"] = 32, ["name"] = "stairs:stair_steelblock"}, {["x"] = 1, ["param2"] = 1, ["y"] = 0, ["param1"] = 94, ["z"] = 33, ["name"] = "stairs:stair_steelblock"}, {["x"] = 1, ["param2"] = 1, ["y"] = 0, ["param1"] = 110, ["z"] = 34, ["name"] = "stairs:stair_steelblock"}, {["x"] = 1, ["param2"] = 1, ["y"] = 0, ["param1"] = 110, ["z"] = 35, ["name"] = "stairs:stair_steelblock"}, {["x"] = 1, ["param2"] = 1, ["y"] = 0, ["param1"] = 94, ["z"] = 36, ["name"] = "stairs:stair_steelblock"}, {["x"] = 1, ["param2"] = 1, ["y"] = 0, ["param1"] = 94, ["z"] = 37, ["name"] = "stairs:stair_steelblock"}, {["x"] = 1, ["param2"] = 1, ["y"] = 0, ["param1"] = 110, ["z"] = 38, ["name"] = "stairs:stair_steelblock"}, {["x"] = 1, ["param2"] = 1, ["y"] = 0, ["param1"] = 110, ["z"] = 39, ["name"] = "stairs:stair_steelblock"}, {["x"] = 1, ["param2"] = 1, ["y"] = 0, ["param1"] = 94, ["z"] = 40, ["name"] = "stairs:stair_steelblock"}, {["x"] = 1, ["param2"] = 1, ["y"] = 0, ["param1"] = 78, ["z"] = 41, ["name"] = "stairs:stair_steelblock"}, {["x"] = 1, ["param2"] = 1, ["y"] = 0, ["param1"] = 62, ["z"] = 42, ["name"] = "stairs:stair_steelblock"}, {["x"] = 1, ["param2"] = 1, ["y"] = 0, ["param1"] = 46, ["z"] = 43, ["name"] = "stairs:stair_steelblock"}, {["x"] = 1, ["param2"] = 1, ["y"] = 0, ["param1"] = 29, ["z"] = 44, ["name"] = "stairs:stair_steelblock"}, {["x"] = 1, ["param2"] = 1, ["y"] = 0, ["param1"] = 14, ["z"] = 45, ["name"] = "stairs:stair_steelblock"}, {["x"] = 1, ["param2"] = 1, ["y"] = 0, ["param1"] = 14, ["z"] = 46, ["name"] = "stairs:stair_steelblock"}, {["x"] = 1, ["param2"] = 1, ["y"] = 0, ["param1"] = 14, ["z"] = 47, ["name"] = "stairs:stair_steelblock"}, {["x"] = 1, ["param2"] = 1, ["y"] = 0, ["param1"] = 14, ["z"] = 48, ["name"] = "stairs:stair_steelblock"}, {["x"] = 1, ["param2"] = 1, ["y"] = 0, ["param1"] = 14, ["z"] = 49, ["name"] = "stairs:stair_steelblock"}, {["x"] = 1, ["param2"] = 1, ["y"] = 0, ["param1"] = 14, ["z"] = 50, ["name"] = "stairs:stair_steelblock"}, {["x"] = 1, ["param2"] = 1, ["y"] = 0, ["param1"] = 14, ["z"] = 51, ["name"] = "stairs:stair_steelblock"}, {["x"] = 1, ["param2"] = 1, ["y"] = 0, ["param1"] = 14, ["z"] = 52, ["name"] = "stairs:stair_steelblock"}, {["x"] = 1, ["param2"] = 2, ["y"] = 0, ["param1"] = 14, ["z"] = 53, ["name"] = "stairs:stair_outer_steelblock"}, {["x"] = 1, ["y"] = 11, ["z"] = 2, ["name"] = "default:steelblock"}, {["x"] = 1, ["y"] = 11, ["z"] = 3, ["name"] = "default:steelblock"}, {["x"] = 1, ["y"] = 11, ["z"] = 4, ["name"] = "default:steelblock"}, {["x"] = 1, ["y"] = 11, ["z"] = 5, ["name"] = "default:steelblock"}, {["x"] = 1, ["y"] = 11, ["z"] = 6, ["name"] = "default:steelblock"}, {["x"] = 1, ["y"] = 11, ["z"] = 7, ["name"] = "default:steelblock"}, {["x"] = 1, ["y"] = 11, ["z"] = 8, ["name"] = "default:steelblock"}, {["x"] = 1, ["y"] = 11, ["z"] = 9, ["name"] = "default:steelblock"}, {["x"] = 1, ["y"] = 11, ["z"] = 10, ["name"] = "default:steelblock"}, {["x"] = 1, ["y"] = 11, ["z"] = 11, ["name"] = "default:steelblock"}, {["x"] = 1, ["y"] = 11, ["z"] = 12, ["name"] = "default:steelblock"}, {["x"] = 1, ["y"] = 11, ["z"] = 13, ["name"] = "default:steelblock"}, {["x"] = 1, ["y"] = 11, ["z"] = 14, ["name"] = "default:steelblock"}, {["x"] = 1, ["y"] = 11, ["z"] = 15, ["name"] = "default:steelblock"}, {["x"] = 1, ["y"] = 11, ["z"] = 16, ["name"] = "default:steelblock"}, {["x"] = 1, ["y"] = 11, ["z"] = 17, ["name"] = "default:steelblock"}, {["x"] = 1, ["y"] = 11, ["z"] = 18, ["name"] = "default:steelblock"}, {["x"] = 1, ["y"] = 11, ["z"] = 19, ["name"] = "default:steelblock"}, {["x"] = 1, ["y"] = 11, ["z"] = 20, ["name"] = "default:steelblock"}, {["x"] = 1, ["y"] = 11, ["z"] = 21, ["name"] = "default:steelblock"}, {["x"] = 1, ["y"] = 11, ["z"] = 22, ["name"] = "default:steelblock"}, {["x"] = 1, ["y"] = 11, ["z"] = 23, ["name"] = "default:steelblock"}, {["x"] = 1, ["y"] = 11, ["z"] = 24, ["name"] = "default:steelblock"}, {["x"] = 1, ["y"] = 11, ["z"] = 25, ["name"] = "default:steelblock"}, {["x"] = 1, ["y"] = 11, ["z"] = 26, ["name"] = "default:steelblock"}, {["x"] = 1, ["y"] = 11, ["z"] = 27, ["name"] = "default:steelblock"}, {["x"] = 1, ["y"] = 11, ["z"] = 28, ["name"] = "default:steelblock"}, {["x"] = 1, ["y"] = 11, ["z"] = 29, ["name"] = "default:steelblock"}, {["x"] = 1, ["y"] = 11, ["z"] = 30, ["name"] = "default:steelblock"}, {["x"] = 1, ["y"] = 11, ["z"] = 31, ["name"] = "default:steelblock"}, {["x"] = 1, ["y"] = 11, ["z"] = 32, ["name"] = "default:steelblock"}, {["x"] = 1, ["y"] = 11, ["z"] = 33, ["name"] = "default:steelblock"}, {["x"] = 1, ["y"] = 11, ["z"] = 34, ["name"] = "default:steelblock"}, {["x"] = 1, ["y"] = 11, ["z"] = 35, ["name"] = "default:steelblock"}, {["x"] = 1, ["y"] = 11, ["z"] = 36, ["name"] = "default:steelblock"}, {["x"] = 1, ["y"] = 11, ["z"] = 37, ["name"] = "default:steelblock"}, {["x"] = 1, ["y"] = 11, ["z"] = 38, ["name"] = "default:steelblock"}, {["x"] = 1, ["y"] = 11, ["z"] = 39, ["name"] = "default:steelblock"}, {["x"] = 1, ["y"] = 11, ["z"] = 40, ["name"] = "default:steelblock"}, {["x"] = 1, ["y"] = 11, ["z"] = 41, ["name"] = "default:steelblock"}, {["x"] = 1, ["y"] = 11, ["z"] = 42, ["name"] = "default:steelblock"}, {["x"] = 1, ["y"] = 11, ["z"] = 43, ["name"] = "default:steelblock"}, {["x"] = 1, ["y"] = 11, ["z"] = 44, ["name"] = "default:steelblock"}, {["x"] = 1, ["y"] = 11, ["z"] = 45, ["name"] = "default:steelblock"}, {["x"] = 1, ["y"] = 11, ["z"] = 46, ["name"] = "default:steelblock"}, {["x"] = 1, ["y"] = 11, ["z"] = 47, ["name"] = "default:steelblock"}, {["x"] = 1, ["y"] = 11, ["z"] = 48, ["name"] = "default:steelblock"}, {["x"] = 1, ["y"] = 11, ["z"] = 49, ["name"] = "default:steelblock"}, {["x"] = 1, ["y"] = 11, ["z"] = 50, ["name"] = "default:steelblock"}, {["x"] = 1, ["y"] = 11, ["z"] = 51, ["name"] = "default:steelblock"}, {["x"] = 1, ["y"] = 11, ["z"] = 52, ["name"] = "default:steelblock"}, {["x"] = 1, ["y"] = 11, ["z"] = 53, ["name"] = "default:steelblock"}, {["x"] = 2, ["y"] = 0, ["param1"] = 30, ["z"] = 2, ["name"] = "stairs:stair_steelblock"}, {["x"] = 2, ["y"] = 0, ["param1"] = 15, ["z"] = 3, ["name"] = "default:steelblock"}, {["x"] = 2, ["y"] = 0, ["param1"] = 15, ["z"] = 4, ["name"] = "default:steelblock"}, {["x"] = 2, ["y"] = 0, ["param1"] = 15, ["z"] = 5, ["name"] = "default:steelblock"}, {["x"] = 2, ["y"] = 0, ["param1"] = 15, ["z"] = 6, ["name"] = "default:steelblock"}, {["x"] = 2, ["y"] = 0, ["param1"] = 15, ["z"] = 7, ["name"] = "default:steelblock"}, {["x"] = 2, ["y"] = 0, ["param1"] = 15, ["z"] = 8, ["name"] = "default:steelblock"}, {["x"] = 2, ["y"] = 0, ["param1"] = 15, ["z"] = 9, ["name"] = "default:steelblock"}, {["x"] = 2, ["y"] = 0, ["param1"] = 15, ["z"] = 10, ["name"] = "default:steelblock"}, {["x"] = 2, ["y"] = 0, ["param1"] = 15, ["z"] = 11, ["name"] = "default:steelblock"}, {["x"] = 2, ["y"] = 0, ["param1"] = 15, ["z"] = 12, ["name"] = "default:steelblock"}, {["x"] = 2, ["y"] = 0, ["param1"] = 15, ["z"] = 13, ["name"] = "default:steelblock"}, {["x"] = 2, ["y"] = 0, ["param1"] = 15, ["z"] = 14, ["name"] = "default:steelblock"}, {["x"] = 2, ["y"] = 0, ["param1"] = 15, ["z"] = 15, ["name"] = "default:steelblock"}, {["x"] = 2, ["y"] = 0, ["param1"] = 15, ["z"] = 16, ["name"] = "default:steelblock"}, {["x"] = 2, ["y"] = 0, ["param1"] = 15, ["z"] = 17, ["name"] = "default:steelblock"}, {["x"] = 2, ["y"] = 0, ["param1"] = 15, ["z"] = 18, ["name"] = "default:steelblock"}, {["x"] = 2, ["y"] = 0, ["param1"] = 15, ["z"] = 19, ["name"] = "default:steelblock"}, {["x"] = 2, ["y"] = 0, ["param1"] = 15, ["z"] = 20, ["name"] = "default:steelblock"}, {["x"] = 2, ["y"] = 0, ["param1"] = 15, ["z"] = 21, ["name"] = "default:steelblock"}, {["x"] = 2, ["y"] = 0, ["param1"] = 15, ["z"] = 22, ["name"] = "default:steelblock"}, {["x"] = 2, ["y"] = 0, ["param1"] = 15, ["z"] = 23, ["name"] = "default:steelblock"}, {["x"] = 2, ["y"] = 0, ["param1"] = 15, ["z"] = 24, ["name"] = "default:steelblock"}, {["x"] = 2, ["y"] = 0, ["param1"] = 15, ["z"] = 25, ["name"] = "default:steelblock"}, {["x"] = 2, ["y"] = 0, ["param1"] = 15, ["z"] = 26, ["name"] = "default:steelblock"}, {["x"] = 2, ["y"] = 0, ["param1"] = 15, ["z"] = 27, ["name"] = "default:steelblock"}, {["x"] = 2, ["y"] = 0, ["param1"] = 15, ["z"] = 28, ["name"] = "default:steelblock"}, {["x"] = 2, ["y"] = 0, ["param1"] = 15, ["z"] = 29, ["name"] = "default:steelblock"}, {["x"] = 2, ["y"] = 0, ["param1"] = 15, ["z"] = 30, ["name"] = "default:steelblock"}, {["x"] = 2, ["y"] = 0, ["param1"] = 15, ["z"] = 31, ["name"] = "default:steelblock"}, {["x"] = 2, ["y"] = 0, ["param1"] = 15, ["z"] = 32, ["name"] = "default:steelblock"}, {["x"] = 2, ["y"] = 0, ["param1"] = 15, ["z"] = 33, ["name"] = "default:steelblock"}, {["x"] = 2, ["y"] = 0, ["param1"] = 15, ["z"] = 34, ["name"] = "default:steelblock"}, {["x"] = 2, ["y"] = 0, ["param1"] = 15, ["z"] = 35, ["name"] = "default:steelblock"}, {["x"] = 2, ["y"] = 0, ["param1"] = 15, ["z"] = 36, ["name"] = "default:steelblock"}, {["x"] = 2, ["y"] = 0, ["param1"] = 15, ["z"] = 37, ["name"] = "default:steelblock"}, {["x"] = 2, ["y"] = 0, ["param1"] = 15, ["z"] = 38, ["name"] = "default:steelblock"}, {["x"] = 2, ["y"] = 0, ["param1"] = 15, ["z"] = 39, ["name"] = "default:steelblock"}, {["x"] = 2, ["y"] = 0, ["param1"] = 15, ["z"] = 40, ["name"] = "default:steelblock"}, {["x"] = 2, ["y"] = 0, ["param1"] = 15, ["z"] = 41, ["name"] = "default:steelblock"}, {["x"] = 2, ["y"] = 0, ["param1"] = 15, ["z"] = 42, ["name"] = "default:steelblock"}, {["x"] = 2, ["y"] = 0, ["param1"] = 15, ["z"] = 43, ["name"] = "default:steelblock"}, {["x"] = 2, ["y"] = 0, ["param1"] = 15, ["z"] = 44, ["name"] = "default:steelblock"}, {["x"] = 2, ["y"] = 0, ["param1"] = 15, ["z"] = 45, ["name"] = "default:steelblock"}, {["x"] = 2, ["y"] = 0, ["param1"] = 15, ["z"] = 46, ["name"] = "default:steelblock"}, {["x"] = 2, ["y"] = 0, ["param1"] = 15, ["z"] = 47, ["name"] = "default:steelblock"}, {["x"] = 2, ["y"] = 0, ["param1"] = 15, ["z"] = 48, ["name"] = "default:steelblock"}, {["x"] = 2, ["y"] = 0, ["param1"] = 15, ["z"] = 49, ["name"] = "default:steelblock"}, {["x"] = 2, ["y"] = 0, ["param1"] = 15, ["z"] = 50, ["name"] = "default:steelblock"}, {["x"] = 2, ["y"] = 0, ["param1"] = 15, ["z"] = 51, ["name"] = "default:steelblock"}, {["x"] = 2, ["y"] = 0, ["param1"] = 15, ["z"] = 52, ["name"] = "default:steelblock"}, {["x"] = 2, ["param2"] = 2, ["y"] = 0, ["param1"] = 14, ["z"] = 53, ["name"] = "stairs:stair_steelblock"}, {["x"] = 2, ["y"] = 1, ["param1"] = 15, ["z"] = 3, ["name"] = "default:steelblock"}, {["x"] = 2, ["y"] = 1, ["param1"] = 15, ["z"] = 4, ["name"] = "default:steelblock"}, {["x"] = 2, ["y"] = 1, ["param1"] = 15, ["z"] = 5, ["name"] = "default:steelblock"}, {["x"] = 2, ["y"] = 1, ["param1"] = 15, ["z"] = 6, ["name"] = "default:steelblock"}, {["x"] = 2, ["y"] = 1, ["param1"] = 15, ["z"] = 7, ["name"] = "default:steelblock"}, {["x"] = 2, ["y"] = 1, ["param1"] = 15, ["z"] = 8, ["name"] = "default:steelblock"}, {["x"] = 2, ["y"] = 1, ["param1"] = 15, ["z"] = 9, ["name"] = "default:steelblock"}, {["x"] = 2, ["y"] = 1, ["param1"] = 15, ["z"] = 10, ["name"] = "default:steelblock"}, {["x"] = 2, ["y"] = 1, ["param1"] = 15, ["z"] = 11, ["name"] = "default:steelblock"}, {["x"] = 2, ["y"] = 1, ["param1"] = 15, ["z"] = 12, ["name"] = "default:steelblock"}, {["x"] = 2, ["y"] = 1, ["param1"] = 15, ["z"] = 13, ["name"] = "default:steelblock"}, {["x"] = 2, ["y"] = 1, ["param1"] = 15, ["z"] = 14, ["name"] = "default:steelblock"}, {["x"] = 2, ["y"] = 1, ["param1"] = 15, ["z"] = 15, ["name"] = "default:steelblock"}, {["x"] = 2, ["y"] = 1, ["param1"] = 15, ["z"] = 16, ["name"] = "default:steelblock"}, {["x"] = 2, ["y"] = 1, ["param1"] = 15, ["z"] = 17, ["name"] = "default:steelblock"}, {["x"] = 2, ["y"] = 1, ["param1"] = 15, ["z"] = 18, ["name"] = "default:steelblock"}, {["x"] = 2, ["y"] = 1, ["param1"] = 15, ["z"] = 19, ["name"] = "default:steelblock"}, {["x"] = 2, ["y"] = 1, ["param1"] = 15, ["z"] = 20, ["name"] = "default:steelblock"}, {["x"] = 2, ["y"] = 1, ["param1"] = 15, ["z"] = 21, ["name"] = "default:steelblock"}, {["x"] = 2, ["y"] = 1, ["param1"] = 15, ["z"] = 22, ["name"] = "default:steelblock"}, {["x"] = 2, ["y"] = 1, ["param1"] = 15, ["z"] = 23, ["name"] = "default:steelblock"}, {["x"] = 2, ["y"] = 1, ["param1"] = 15, ["z"] = 24, ["name"] = "default:steelblock"}, {["x"] = 2, ["y"] = 1, ["param1"] = 15, ["z"] = 25, ["name"] = "default:steelblock"}, {["x"] = 2, ["y"] = 1, ["param1"] = 15, ["z"] = 26, ["name"] = "default:steelblock"}, {["x"] = 2, ["y"] = 1, ["param1"] = 15, ["z"] = 27, ["name"] = "default:steelblock"}, {["x"] = 2, ["y"] = 1, ["param1"] = 15, ["z"] = 28, ["name"] = "default:steelblock"}, {["x"] = 2, ["y"] = 1, ["param1"] = 15, ["z"] = 29, ["name"] = "default:steelblock"}, {["x"] = 2, ["y"] = 1, ["param1"] = 15, ["z"] = 30, ["name"] = "default:steelblock"}, {["x"] = 2, ["y"] = 1, ["param1"] = 15, ["z"] = 31, ["name"] = "default:steelblock"}, {["x"] = 2, ["y"] = 1, ["param1"] = 15, ["z"] = 32, ["name"] = "default:steelblock"}, {["x"] = 2, ["y"] = 1, ["param1"] = 15, ["z"] = 33, ["name"] = "default:steelblock"}, {["x"] = 2, ["y"] = 1, ["param1"] = 15, ["z"] = 34, ["name"] = "default:steelblock"}, {["x"] = 2, ["y"] = 1, ["param1"] = 15, ["z"] = 35, ["name"] = "default:steelblock"}, {["x"] = 2, ["y"] = 1, ["param1"] = 15, ["z"] = 36, ["name"] = "default:steelblock"}, {["x"] = 2, ["y"] = 1, ["param1"] = 15, ["z"] = 37, ["name"] = "default:steelblock"}, {["x"] = 2, ["y"] = 1, ["param1"] = 15, ["z"] = 38, ["name"] = "default:steelblock"}, {["x"] = 2, ["y"] = 1, ["param1"] = 15, ["z"] = 39, ["name"] = "default:steelblock"}, {["x"] = 2, ["y"] = 1, ["param1"] = 15, ["z"] = 40, ["name"] = "default:steelblock"}, {["x"] = 2, ["y"] = 1, ["param1"] = 15, ["z"] = 41, ["name"] = "default:steelblock"}, {["x"] = 2, ["y"] = 1, ["param1"] = 15, ["z"] = 42, ["name"] = "default:steelblock"}, {["x"] = 2, ["y"] = 1, ["param1"] = 15, ["z"] = 45, ["name"] = "default:steelblock"}, {["x"] = 2, ["y"] = 1, ["param1"] = 15, ["z"] = 46, ["name"] = "default:steelblock"}, {["x"] = 2, ["y"] = 1, ["param1"] = 15, ["z"] = 47, ["name"] = "default:steelblock"}, {["x"] = 2, ["y"] = 1, ["param1"] = 15, ["z"] = 50, ["name"] = "default:steelblock"}, {["x"] = 2, ["y"] = 1, ["param1"] = 15, ["z"] = 51, ["name"] = "default:steelblock"}, {["x"] = 2, ["y"] = 1, ["param1"] = 15, ["z"] = 52, ["name"] = "default:steelblock"}, {["x"] = 2, ["y"] = 2, ["param1"] = 15, ["z"] = 3, ["name"] = "default:steelblock"}, {["x"] = 2, ["y"] = 2, ["param1"] = 15, ["z"] = 4, ["name"] = "default:steelblock"}, {["x"] = 2, ["y"] = 2, ["param1"] = 15, ["z"] = 5, ["name"] = "default:steelblock"}, {["x"] = 2, ["y"] = 2, ["param1"] = 15, ["z"] = 6, ["name"] = "default:steelblock"}, {["x"] = 2, ["y"] = 2, ["param1"] = 15, ["z"] = 7, ["name"] = "default:steelblock"}, {["x"] = 2, ["y"] = 2, ["param1"] = 15, ["z"] = 8, ["name"] = "default:steelblock"}, {["x"] = 2, ["y"] = 2, ["param1"] = 15, ["z"] = 9, ["name"] = "default:steelblock"}, {["x"] = 2, ["y"] = 2, ["param1"] = 15, ["z"] = 10, ["name"] = "default:steelblock"}, {["x"] = 2, ["y"] = 2, ["param1"] = 15, ["z"] = 11, ["name"] = "default:steelblock"}, {["x"] = 2, ["y"] = 2, ["param1"] = 15, ["z"] = 12, ["name"] = "default:steelblock"}, {["x"] = 2, ["y"] = 2, ["param1"] = 15, ["z"] = 13, ["name"] = "default:steelblock"}, {["x"] = 2, ["y"] = 2, ["param1"] = 15, ["z"] = 14, ["name"] = "default:steelblock"}, {["x"] = 2, ["y"] = 2, ["param1"] = 15, ["z"] = 15, ["name"] = "default:steelblock"}, {["x"] = 2, ["y"] = 2, ["param1"] = 15, ["z"] = 16, ["name"] = "default:steelblock"}, {["x"] = 2, ["y"] = 2, ["param1"] = 15, ["z"] = 17, ["name"] = "default:steelblock"}, {["x"] = 2, ["y"] = 2, ["param1"] = 15, ["z"] = 18, ["name"] = "default:steelblock"}, {["x"] = 2, ["y"] = 2, ["param1"] = 15, ["z"] = 19, ["name"] = "default:steelblock"}, {["x"] = 2, ["y"] = 2, ["param1"] = 15, ["z"] = 20, ["name"] = "default:steelblock"}, {["x"] = 2, ["y"] = 2, ["param1"] = 15, ["z"] = 21, ["name"] = "default:steelblock"}, {["x"] = 2, ["y"] = 2, ["param1"] = 15, ["z"] = 22, ["name"] = "default:steelblock"}, {["x"] = 2, ["y"] = 2, ["param1"] = 15, ["z"] = 23, ["name"] = "default:steelblock"}, {["x"] = 2, ["y"] = 2, ["param1"] = 15, ["z"] = 24, ["name"] = "default:steelblock"}, {["x"] = 2, ["y"] = 2, ["param1"] = 15, ["z"] = 25, ["name"] = "default:steelblock"}, {["x"] = 2, ["y"] = 2, ["param1"] = 15, ["z"] = 26, ["name"] = "default:steelblock"}, {["x"] = 2, ["y"] = 2, ["param1"] = 15, ["z"] = 27, ["name"] = "default:steelblock"}, {["x"] = 2, ["y"] = 2, ["param1"] = 15, ["z"] = 28, ["name"] = "default:steelblock"}, {["x"] = 2, ["y"] = 2, ["param1"] = 15, ["z"] = 29, ["name"] = "default:steelblock"}, {["x"] = 2, ["y"] = 2, ["param1"] = 15, ["z"] = 30, ["name"] = "default:steelblock"}, {["x"] = 2, ["y"] = 2, ["param1"] = 15, ["z"] = 31, ["name"] = "default:steelblock"}, {["x"] = 2, ["y"] = 2, ["param1"] = 15, ["z"] = 32, ["name"] = "default:steelblock"}, {["x"] = 2, ["y"] = 2, ["param1"] = 15, ["z"] = 33, ["name"] = "default:steelblock"}, {["x"] = 2, ["y"] = 2, ["param1"] = 15, ["z"] = 34, ["name"] = "default:steelblock"}, {["x"] = 2, ["y"] = 2, ["param1"] = 15, ["z"] = 35, ["name"] = "default:steelblock"}, {["x"] = 2, ["y"] = 2, ["param1"] = 15, ["z"] = 36, ["name"] = "default:steelblock"}, {["x"] = 2, ["y"] = 2, ["param1"] = 15, ["z"] = 37, ["name"] = "default:steelblock"}, {["x"] = 2, ["y"] = 2, ["param1"] = 15, ["z"] = 38, ["name"] = "default:steelblock"}, {["x"] = 2, ["y"] = 2, ["param1"] = 15, ["z"] = 39, ["name"] = "default:steelblock"}, {["x"] = 2, ["y"] = 2, ["param1"] = 15, ["z"] = 40, ["name"] = "default:steelblock"}, {["x"] = 2, ["y"] = 2, ["param1"] = 15, ["z"] = 41, ["name"] = "default:steelblock"}, {["x"] = 2, ["y"] = 2, ["param1"] = 15, ["z"] = 42, ["name"] = "default:steelblock"}, {["x"] = 2, ["y"] = 2, ["param1"] = 15, ["z"] = 45, ["name"] = "default:steelblock"}, {["x"] = 2, ["y"] = 2, ["param1"] = 15, ["z"] = 46, ["name"] = "default:steelblock"}, {["x"] = 2, ["y"] = 2, ["param1"] = 15, ["z"] = 47, ["name"] = "default:steelblock"}, {["x"] = 2, ["y"] = 2, ["param1"] = 15, ["z"] = 50, ["name"] = "default:steelblock"}, {["x"] = 2, ["y"] = 2, ["param1"] = 15, ["z"] = 51, ["name"] = "default:steelblock"}, {["x"] = 2, ["y"] = 2, ["param1"] = 15, ["z"] = 52, ["name"] = "default:steelblock"}, {["x"] = 2, ["y"] = 3, ["param1"] = 15, ["z"] = 3, ["name"] = "default:steelblock"}, {["x"] = 2, ["y"] = 3, ["param1"] = 15, ["z"] = 4, ["name"] = "default:steelblock"}, {["x"] = 2, ["y"] = 3, ["param1"] = 15, ["z"] = 5, ["name"] = "default:steelblock"}, {["x"] = 2, ["y"] = 3, ["param1"] = 15, ["z"] = 6, ["name"] = "default:steelblock"}, {["x"] = 2, ["y"] = 3, ["param1"] = 15, ["z"] = 7, ["name"] = "default:steelblock"}, {["x"] = 2, ["y"] = 3, ["param1"] = 15, ["z"] = 8, ["name"] = "default:steelblock"}, {["x"] = 2, ["y"] = 3, ["param1"] = 15, ["z"] = 9, ["name"] = "default:steelblock"}, {["x"] = 2, ["y"] = 3, ["param1"] = 15, ["z"] = 10, ["name"] = "default:steelblock"}, {["x"] = 2, ["y"] = 3, ["param1"] = 15, ["z"] = 11, ["name"] = "default:steelblock"}, {["x"] = 2, ["y"] = 3, ["param1"] = 15, ["z"] = 12, ["name"] = "default:steelblock"}, {["x"] = 2, ["y"] = 3, ["param1"] = 15, ["z"] = 13, ["name"] = "default:steelblock"}, {["x"] = 2, ["y"] = 3, ["param1"] = 15, ["z"] = 14, ["name"] = "default:steelblock"}, {["x"] = 2, ["y"] = 3, ["param1"] = 15, ["z"] = 15, ["name"] = "default:steelblock"}, {["x"] = 2, ["y"] = 3, ["param1"] = 15, ["z"] = 16, ["name"] = "default:steelblock"}, {["x"] = 2, ["y"] = 3, ["param1"] = 15, ["z"] = 17, ["name"] = "default:steelblock"}, {["x"] = 2, ["y"] = 3, ["param1"] = 15, ["z"] = 18, ["name"] = "default:steelblock"}, {["x"] = 2, ["y"] = 3, ["param1"] = 15, ["z"] = 19, ["name"] = "default:steelblock"}, {["x"] = 2, ["y"] = 3, ["param1"] = 15, ["z"] = 20, ["name"] = "default:steelblock"}, {["x"] = 2, ["y"] = 3, ["param1"] = 15, ["z"] = 21, ["name"] = "default:steelblock"}, {["x"] = 2, ["y"] = 3, ["param1"] = 15, ["z"] = 22, ["name"] = "default:steelblock"}, {["x"] = 2, ["y"] = 3, ["param1"] = 15, ["z"] = 23, ["name"] = "default:steelblock"}, {["x"] = 2, ["y"] = 3, ["param1"] = 15, ["z"] = 24, ["name"] = "default:steelblock"}, {["x"] = 2, ["y"] = 3, ["param1"] = 15, ["z"] = 25, ["name"] = "default:steelblock"}, {["x"] = 2, ["y"] = 3, ["param1"] = 15, ["z"] = 26, ["name"] = "default:steelblock"}, {["x"] = 2, ["y"] = 3, ["param1"] = 15, ["z"] = 27, ["name"] = "default:steelblock"}, {["x"] = 2, ["y"] = 3, ["param1"] = 15, ["z"] = 28, ["name"] = "default:steelblock"}, {["x"] = 2, ["y"] = 3, ["param1"] = 15, ["z"] = 29, ["name"] = "default:steelblock"}, {["x"] = 2, ["y"] = 3, ["param1"] = 15, ["z"] = 30, ["name"] = "default:steelblock"}, {["x"] = 2, ["y"] = 3, ["param1"] = 15, ["z"] = 31, ["name"] = "default:steelblock"}, {["x"] = 2, ["y"] = 3, ["param1"] = 15, ["z"] = 32, ["name"] = "default:steelblock"}, {["x"] = 2, ["y"] = 3, ["param1"] = 15, ["z"] = 33, ["name"] = "default:steelblock"}, {["x"] = 2, ["y"] = 3, ["param1"] = 15, ["z"] = 34, ["name"] = "default:steelblock"}, {["x"] = 2, ["y"] = 3, ["param1"] = 15, ["z"] = 35, ["name"] = "default:steelblock"}, {["x"] = 2, ["y"] = 3, ["param1"] = 15, ["z"] = 36, ["name"] = "default:steelblock"}, {["x"] = 2, ["y"] = 3, ["param1"] = 15, ["z"] = 37, ["name"] = "default:steelblock"}, {["x"] = 2, ["y"] = 3, ["param1"] = 15, ["z"] = 38, ["name"] = "default:steelblock"}, {["x"] = 2, ["y"] = 3, ["param1"] = 15, ["z"] = 39, ["name"] = "default:steelblock"}, {["x"] = 2, ["y"] = 3, ["param1"] = 15, ["z"] = 40, ["name"] = "default:steelblock"}, {["x"] = 2, ["y"] = 3, ["param1"] = 15, ["z"] = 41, ["name"] = "default:steelblock"}, {["x"] = 2, ["y"] = 3, ["param1"] = 15, ["z"] = 42, ["name"] = "default:steelblock"}, {["x"] = 2, ["y"] = 3, ["param1"] = 15, ["z"] = 45, ["name"] = "default:steelblock"}, {["x"] = 2, ["y"] = 3, ["param1"] = 15, ["z"] = 46, ["name"] = "default:steelblock"}, {["x"] = 2, ["y"] = 3, ["param1"] = 15, ["z"] = 47, ["name"] = "default:steelblock"}, {["x"] = 2, ["y"] = 3, ["param1"] = 15, ["z"] = 50, ["name"] = "default:steelblock"}, {["x"] = 2, ["y"] = 3, ["param1"] = 15, ["z"] = 51, ["name"] = "default:steelblock"}, {["x"] = 2, ["y"] = 3, ["param1"] = 15, ["z"] = 52, ["name"] = "default:steelblock"}, {["x"] = 2, ["y"] = 4, ["param1"] = 15, ["z"] = 3, ["name"] = "default:steelblock"}, {["x"] = 2, ["y"] = 4, ["param1"] = 15, ["z"] = 4, ["name"] = "default:steelblock"}, {["x"] = 2, ["y"] = 4, ["param1"] = 15, ["z"] = 5, ["name"] = "default:steelblock"}, {["x"] = 2, ["y"] = 4, ["param1"] = 15, ["z"] = 6, ["name"] = "default:steelblock"}, {["x"] = 2, ["y"] = 4, ["param1"] = 15, ["z"] = 7, ["name"] = "default:steelblock"}, {["x"] = 2, ["y"] = 4, ["param1"] = 15, ["z"] = 8, ["name"] = "default:steelblock"}, {["x"] = 2, ["y"] = 4, ["param1"] = 15, ["z"] = 9, ["name"] = "default:steelblock"}, {["x"] = 2, ["y"] = 4, ["param1"] = 15, ["z"] = 10, ["name"] = "default:steelblock"}, {["x"] = 2, ["y"] = 4, ["param1"] = 15, ["z"] = 11, ["name"] = "default:steelblock"}, {["x"] = 2, ["y"] = 4, ["param1"] = 15, ["z"] = 12, ["name"] = "default:steelblock"}, {["x"] = 2, ["y"] = 4, ["param1"] = 15, ["z"] = 13, ["name"] = "default:steelblock"}, {["x"] = 2, ["y"] = 4, ["param1"] = 15, ["z"] = 14, ["name"] = "default:steelblock"}, {["x"] = 2, ["y"] = 4, ["param1"] = 15, ["z"] = 15, ["name"] = "default:steelblock"}, {["x"] = 2, ["y"] = 4, ["param1"] = 15, ["z"] = 16, ["name"] = "default:steelblock"}, {["x"] = 2, ["y"] = 4, ["param1"] = 15, ["z"] = 17, ["name"] = "default:steelblock"}, {["x"] = 2, ["y"] = 4, ["param1"] = 15, ["z"] = 18, ["name"] = "default:steelblock"}, {["x"] = 2, ["y"] = 4, ["param1"] = 15, ["z"] = 19, ["name"] = "default:steelblock"}, {["x"] = 2, ["y"] = 4, ["param1"] = 15, ["z"] = 20, ["name"] = "default:steelblock"}, {["x"] = 2, ["y"] = 4, ["param1"] = 15, ["z"] = 21, ["name"] = "default:steelblock"}, {["x"] = 2, ["y"] = 4, ["param1"] = 15, ["z"] = 22, ["name"] = "default:steelblock"}, {["x"] = 2, ["y"] = 4, ["param1"] = 15, ["z"] = 23, ["name"] = "default:steelblock"}, {["x"] = 2, ["y"] = 4, ["param1"] = 15, ["z"] = 24, ["name"] = "default:steelblock"}, {["x"] = 2, ["y"] = 4, ["param1"] = 15, ["z"] = 25, ["name"] = "default:steelblock"}, {["x"] = 2, ["y"] = 4, ["param1"] = 15, ["z"] = 26, ["name"] = "default:steelblock"}, {["x"] = 2, ["y"] = 4, ["param1"] = 15, ["z"] = 27, ["name"] = "default:steelblock"}, {["x"] = 2, ["y"] = 4, ["param1"] = 15, ["z"] = 28, ["name"] = "default:steelblock"}, {["x"] = 2, ["y"] = 4, ["param1"] = 15, ["z"] = 29, ["name"] = "default:steelblock"}, {["x"] = 2, ["y"] = 4, ["param1"] = 15, ["z"] = 30, ["name"] = "default:steelblock"}, {["x"] = 2, ["y"] = 4, ["param1"] = 15, ["z"] = 31, ["name"] = "default:steelblock"}, {["x"] = 2, ["y"] = 4, ["param1"] = 15, ["z"] = 32, ["name"] = "default:steelblock"}, {["x"] = 2, ["y"] = 4, ["param1"] = 15, ["z"] = 33, ["name"] = "default:steelblock"}, {["x"] = 2, ["param2"] = 1, ["y"] = 4, ["param1"] = 190, ["z"] = 34, ["name"] = "xpanes:pane_flat"}, {["x"] = 2, ["param2"] = 3, ["y"] = 4, ["param1"] = 190, ["z"] = 35, ["name"] = "xpanes:pane_flat"}, {["x"] = 2, ["y"] = 4, ["param1"] = 15, ["z"] = 36, ["name"] = "default:steelblock"}, {["x"] = 2, ["y"] = 4, ["param1"] = 15, ["z"] = 37, ["name"] = "default:steelblock"}, {["x"] = 2, ["param2"] = 1, ["y"] = 4, ["param1"] = 190, ["z"] = 38, ["name"] = "xpanes:pane_flat"}, {["x"] = 2, ["param2"] = 3, ["y"] = 4, ["param1"] = 190, ["z"] = 39, ["name"] = "xpanes:pane_flat"}, {["x"] = 2, ["y"] = 4, ["param1"] = 15, ["z"] = 40, ["name"] = "default:steelblock"}, {["x"] = 2, ["y"] = 4, ["param1"] = 15, ["z"] = 41, ["name"] = "default:steelblock"}, {["x"] = 2, ["y"] = 4, ["param1"] = 15, ["z"] = 42, ["name"] = "default:steelblock"}, {["x"] = 2, ["y"] = 4, ["param1"] = 15, ["z"] = 45, ["name"] = "default:steelblock"}, {["x"] = 2, ["y"] = 4, ["param1"] = 15, ["z"] = 46, ["name"] = "default:steelblock"}, {["x"] = 2, ["y"] = 4, ["param1"] = 15, ["z"] = 47, ["name"] = "default:steelblock"}, {["x"] = 2, ["y"] = 4, ["param1"] = 15, ["z"] = 50, ["name"] = "default:steelblock"}, {["x"] = 2, ["y"] = 4, ["param1"] = 15, ["z"] = 51, ["name"] = "default:steelblock"}, {["x"] = 2, ["y"] = 4, ["param1"] = 15, ["z"] = 52, ["name"] = "default:steelblock"}, {["x"] = 2, ["y"] = 5, ["param1"] = 15, ["z"] = 3, ["name"] = "default:steelblock"}, {["x"] = 2, ["y"] = 5, ["param1"] = 15, ["z"] = 4, ["name"] = "default:steelblock"}, {["x"] = 2, ["y"] = 5, ["param1"] = 15, ["z"] = 5, ["name"] = "default:steelblock"}, {["x"] = 2, ["y"] = 5, ["param1"] = 15, ["z"] = 6, ["name"] = "default:steelblock"}, {["x"] = 2, ["y"] = 5, ["param1"] = 15, ["z"] = 7, ["name"] = "default:steelblock"}, {["x"] = 2, ["y"] = 5, ["param1"] = 15, ["z"] = 8, ["name"] = "default:steelblock"}, {["x"] = 2, ["y"] = 5, ["param1"] = 15, ["z"] = 9, ["name"] = "default:steelblock"}, {["x"] = 2, ["y"] = 5, ["param1"] = 15, ["z"] = 10, ["name"] = "default:steelblock"}, {["x"] = 2, ["y"] = 5, ["param1"] = 15, ["z"] = 11, ["name"] = "default:steelblock"}, {["x"] = 2, ["y"] = 5, ["param1"] = 15, ["z"] = 12, ["name"] = "default:steelblock"}, {["x"] = 2, ["y"] = 5, ["param1"] = 15, ["z"] = 13, ["name"] = "default:steelblock"}, {["x"] = 2, ["y"] = 5, ["param1"] = 15, ["z"] = 14, ["name"] = "default:steelblock"}, {["x"] = 2, ["y"] = 5, ["param1"] = 15, ["z"] = 15, ["name"] = "default:steelblock"}, {["x"] = 2, ["y"] = 5, ["param1"] = 15, ["z"] = 16, ["name"] = "default:steelblock"}, {["x"] = 2, ["y"] = 5, ["param1"] = 15, ["z"] = 17, ["name"] = "default:steelblock"}, {["x"] = 2, ["y"] = 5, ["param1"] = 15, ["z"] = 18, ["name"] = "default:steelblock"}, {["x"] = 2, ["y"] = 5, ["param1"] = 15, ["z"] = 19, ["name"] = "default:steelblock"}, {["x"] = 2, ["y"] = 5, ["param1"] = 15, ["z"] = 20, ["name"] = "default:steelblock"}, {["x"] = 2, ["y"] = 5, ["param1"] = 15, ["z"] = 21, ["name"] = "default:steelblock"}, {["x"] = 2, ["y"] = 5, ["param1"] = 15, ["z"] = 22, ["name"] = "default:steelblock"}, {["x"] = 2, ["y"] = 5, ["param1"] = 15, ["z"] = 23, ["name"] = "default:steelblock"}, {["x"] = 2, ["y"] = 5, ["param1"] = 15, ["z"] = 24, ["name"] = "default:steelblock"}, {["x"] = 2, ["y"] = 5, ["param1"] = 15, ["z"] = 25, ["name"] = "default:steelblock"}, {["x"] = 2, ["y"] = 5, ["param1"] = 15, ["z"] = 26, ["name"] = "default:steelblock"}, {["x"] = 2, ["y"] = 5, ["param1"] = 15, ["z"] = 27, ["name"] = "default:steelblock"}, {["x"] = 2, ["y"] = 5, ["param1"] = 15, ["z"] = 28, ["name"] = "default:steelblock"}, {["x"] = 2, ["y"] = 5, ["param1"] = 15, ["z"] = 29, ["name"] = "default:steelblock"}, {["x"] = 2, ["y"] = 5, ["param1"] = 15, ["z"] = 30, ["name"] = "default:steelblock"}, {["x"] = 2, ["y"] = 5, ["param1"] = 15, ["z"] = 31, ["name"] = "default:steelblock"}, {["x"] = 2, ["y"] = 5, ["param1"] = 15, ["z"] = 32, ["name"] = "default:steelblock"}, {["x"] = 2, ["y"] = 5, ["param1"] = 15, ["z"] = 33, ["name"] = "default:steelblock"}, {["x"] = 2, ["y"] = 5, ["param1"] = 15, ["z"] = 34, ["name"] = "default:steelblock"}, {["x"] = 2, ["y"] = 5, ["param1"] = 15, ["z"] = 35, ["name"] = "default:steelblock"}, {["x"] = 2, ["y"] = 5, ["param1"] = 15, ["z"] = 36, ["name"] = "default:steelblock"}, {["x"] = 2, ["y"] = 5, ["param1"] = 15, ["z"] = 37, ["name"] = "default:steelblock"}, {["x"] = 2, ["y"] = 5, ["param1"] = 15, ["z"] = 38, ["name"] = "default:steelblock"}, {["x"] = 2, ["y"] = 5, ["param1"] = 15, ["z"] = 39, ["name"] = "default:steelblock"}, {["x"] = 2, ["y"] = 5, ["param1"] = 15, ["z"] = 40, ["name"] = "default:steelblock"}, {["x"] = 2, ["y"] = 5, ["param1"] = 15, ["z"] = 41, ["name"] = "default:steelblock"}, {["x"] = 2, ["y"] = 5, ["param1"] = 15, ["z"] = 42, ["name"] = "default:steelblock"}, {["x"] = 2, ["y"] = 5, ["param1"] = 15, ["z"] = 45, ["name"] = "default:steelblock"}, {["x"] = 2, ["y"] = 5, ["param1"] = 15, ["z"] = 46, ["name"] = "default:steelblock"}, {["x"] = 2, ["y"] = 5, ["param1"] = 15, ["z"] = 47, ["name"] = "default:steelblock"}, {["x"] = 2, ["y"] = 5, ["param1"] = 15, ["z"] = 50, ["name"] = "default:steelblock"}, {["x"] = 2, ["y"] = 5, ["param1"] = 15, ["z"] = 51, ["name"] = "default:steelblock"}, {["x"] = 2, ["y"] = 5, ["param1"] = 15, ["z"] = 52, ["name"] = "default:steelblock"}, {["x"] = 2, ["y"] = 6, ["param1"] = 15, ["z"] = 3, ["name"] = "default:steelblock"}, {["x"] = 2, ["y"] = 6, ["param1"] = 15, ["z"] = 4, ["name"] = "default:steelblock"}, {["x"] = 2, ["y"] = 6, ["param1"] = 15, ["z"] = 5, ["name"] = "default:steelblock"}, {["x"] = 2, ["y"] = 6, ["param1"] = 15, ["z"] = 6, ["name"] = "default:steelblock"}, {["x"] = 2, ["y"] = 6, ["param1"] = 15, ["z"] = 7, ["name"] = "default:steelblock"}, {["x"] = 2, ["y"] = 6, ["param1"] = 15, ["z"] = 8, ["name"] = "default:steelblock"}, {["x"] = 2, ["y"] = 6, ["param1"] = 15, ["z"] = 9, ["name"] = "default:steelblock"}, {["x"] = 2, ["y"] = 6, ["param1"] = 15, ["z"] = 10, ["name"] = "default:steelblock"}, {["x"] = 2, ["y"] = 6, ["param1"] = 15, ["z"] = 11, ["name"] = "default:steelblock"}, {["x"] = 2, ["y"] = 6, ["param1"] = 15, ["z"] = 12, ["name"] = "default:steelblock"}, {["x"] = 2, ["y"] = 6, ["param1"] = 15, ["z"] = 13, ["name"] = "default:steelblock"}, {["x"] = 2, ["y"] = 6, ["param1"] = 15, ["z"] = 14, ["name"] = "default:steelblock"}, {["x"] = 2, ["y"] = 6, ["param1"] = 15, ["z"] = 15, ["name"] = "default:steelblock"}, {["x"] = 2, ["y"] = 6, ["param1"] = 15, ["z"] = 16, ["name"] = "default:steelblock"}, {["x"] = 2, ["y"] = 6, ["param1"] = 15, ["z"] = 17, ["name"] = "default:steelblock"}, {["x"] = 2, ["y"] = 6, ["param1"] = 15, ["z"] = 18, ["name"] = "default:steelblock"}, {["x"] = 2, ["y"] = 6, ["param1"] = 15, ["z"] = 19, ["name"] = "default:steelblock"}, {["x"] = 2, ["y"] = 6, ["param1"] = 15, ["z"] = 20, ["name"] = "default:steelblock"}, {["x"] = 2, ["y"] = 6, ["param1"] = 15, ["z"] = 21, ["name"] = "default:steelblock"}, {["x"] = 2, ["y"] = 6, ["param1"] = 15, ["z"] = 22, ["name"] = "default:steelblock"}, {["x"] = 2, ["y"] = 6, ["param1"] = 15, ["z"] = 23, ["name"] = "default:steelblock"}, {["x"] = 2, ["y"] = 6, ["param1"] = 15, ["z"] = 24, ["name"] = "default:steelblock"}, {["x"] = 2, ["y"] = 6, ["param1"] = 15, ["z"] = 25, ["name"] = "default:steelblock"}, {["x"] = 2, ["y"] = 6, ["param1"] = 15, ["z"] = 26, ["name"] = "default:steelblock"}, {["x"] = 2, ["y"] = 6, ["param1"] = 15, ["z"] = 27, ["name"] = "default:steelblock"}, {["x"] = 2, ["y"] = 6, ["param1"] = 15, ["z"] = 28, ["name"] = "default:steelblock"}, {["x"] = 2, ["y"] = 6, ["param1"] = 15, ["z"] = 29, ["name"] = "default:steelblock"}, {["x"] = 2, ["y"] = 6, ["param1"] = 15, ["z"] = 30, ["name"] = "default:steelblock"}, {["x"] = 2, ["y"] = 6, ["param1"] = 15, ["z"] = 31, ["name"] = "default:steelblock"}, {["x"] = 2, ["y"] = 6, ["param1"] = 15, ["z"] = 32, ["name"] = "default:steelblock"}, {["x"] = 2, ["y"] = 6, ["param1"] = 15, ["z"] = 33, ["name"] = "default:steelblock"}, {["x"] = 2, ["y"] = 6, ["param1"] = 15, ["z"] = 34, ["name"] = "default:steelblock"}, {["x"] = 2, ["y"] = 6, ["z"] = 35, ["name"] = "default:steelblock"}, {["x"] = 2, ["y"] = 6, ["param1"] = 15, ["z"] = 36, ["name"] = "default:steelblock"}, {["x"] = 2, ["y"] = 6, ["param1"] = 15, ["z"] = 37, ["name"] = "default:steelblock"}, {["x"] = 2, ["y"] = 6, ["param1"] = 15, ["z"] = 38, ["name"] = "default:steelblock"}, {["x"] = 2, ["y"] = 6, ["param1"] = 15, ["z"] = 39, ["name"] = "default:steelblock"}, {["x"] = 2, ["y"] = 6, ["param1"] = 15, ["z"] = 40, ["name"] = "default:steelblock"}, {["x"] = 2, ["y"] = 6, ["param1"] = 15, ["z"] = 41, ["name"] = "default:steelblock"}, {["x"] = 2, ["y"] = 6, ["param1"] = 15, ["z"] = 42, ["name"] = "default:steelblock"}, {["x"] = 2, ["y"] = 6, ["param1"] = 15, ["z"] = 45, ["name"] = "default:steelblock"}, {["x"] = 2, ["y"] = 6, ["param1"] = 15, ["z"] = 46, ["name"] = "default:steelblock"}, {["x"] = 2, ["y"] = 6, ["param1"] = 15, ["z"] = 47, ["name"] = "default:steelblock"}, {["x"] = 2, ["y"] = 6, ["param1"] = 15, ["z"] = 50, ["name"] = "default:steelblock"}, {["x"] = 2, ["y"] = 6, ["param1"] = 15, ["z"] = 51, ["name"] = "default:steelblock"}, {["x"] = 2, ["y"] = 6, ["param1"] = 15, ["z"] = 52, ["name"] = "default:steelblock"}, {["x"] = 2, ["y"] = 7, ["param1"] = 15, ["z"] = 3, ["name"] = "default:steelblock"}, {["x"] = 2, ["y"] = 7, ["param1"] = 15, ["z"] = 4, ["name"] = "default:steelblock"}, {["x"] = 2, ["y"] = 7, ["param1"] = 15, ["z"] = 5, ["name"] = "default:steelblock"}, {["x"] = 2, ["param2"] = 1, ["y"] = 7, ["param1"] = 206, ["z"] = 6, ["name"] = "xpanes:pane_flat"}, {["x"] = 2, ["param2"] = 3, ["y"] = 7, ["param1"] = 206, ["z"] = 7, ["name"] = "xpanes:pane_flat"}, {["x"] = 2, ["param2"] = 3, ["y"] = 7, ["param1"] = 206, ["z"] = 8, ["name"] = "xpanes:pane_flat"}, {["x"] = 2, ["y"] = 7, ["param1"] = 15, ["z"] = 9, ["name"] = "default:steelblock"}, {["x"] = 2, ["y"] = 7, ["param1"] = 15, ["z"] = 10, ["name"] = "default:steelblock"}, {["x"] = 2, ["y"] = 7, ["param1"] = 15, ["z"] = 11, ["name"] = "default:steelblock"}, {["x"] = 2, ["param2"] = 1, ["y"] = 7, ["param1"] = 206, ["z"] = 12, ["name"] = "xpanes:pane_flat"}, {["x"] = 2, ["param2"] = 3, ["y"] = 7, ["param1"] = 206, ["z"] = 13, ["name"] = "xpanes:pane_flat"}, {["x"] = 2, ["param2"] = 3, ["y"] = 7, ["param1"] = 190, ["z"] = 14, ["name"] = "xpanes:pane_flat"}, {["x"] = 2, ["y"] = 7, ["param1"] = 15, ["z"] = 15, ["name"] = "default:steelblock"}, {["x"] = 2, ["y"] = 7, ["param1"] = 15, ["z"] = 16, ["name"] = "default:steelblock"}, {["x"] = 2, ["y"] = 7, ["param1"] = 15, ["z"] = 17, ["name"] = "default:steelblock"}, {["x"] = 2, ["y"] = 7, ["param1"] = 15, ["z"] = 18, ["name"] = "default:steelblock"}, {["x"] = 2, ["y"] = 7, ["param1"] = 15, ["z"] = 19, ["name"] = "default:steelblock"}, {["x"] = 2, ["param2"] = 1, ["y"] = 7, ["param1"] = 206, ["z"] = 20, ["name"] = "xpanes:pane_flat"}, {["x"] = 2, ["param2"] = 3, ["y"] = 7, ["param1"] = 206, ["z"] = 21, ["name"] = "xpanes:pane_flat"}, {["x"] = 2, ["param2"] = 3, ["y"] = 7, ["param1"] = 206, ["z"] = 22, ["name"] = "xpanes:pane_flat"}, {["x"] = 2, ["y"] = 7, ["param1"] = 15, ["z"] = 23, ["name"] = "default:steelblock"}, {["x"] = 2, ["y"] = 7, ["param1"] = 15, ["z"] = 24, ["name"] = "default:steelblock"}, {["x"] = 2, ["y"] = 7, ["param1"] = 15, ["z"] = 25, ["name"] = "default:steelblock"}, {["x"] = 2, ["param2"] = 1, ["y"] = 7, ["param1"] = 206, ["z"] = 26, ["name"] = "xpanes:pane_flat"}, {["x"] = 2, ["param2"] = 3, ["y"] = 7, ["param1"] = 206, ["z"] = 27, ["name"] = "xpanes:pane_flat"}, {["x"] = 2, ["param2"] = 3, ["y"] = 7, ["param1"] = 190, ["z"] = 28, ["name"] = "xpanes:pane_flat"}, {["x"] = 2, ["y"] = 7, ["z"] = 29, ["name"] = "default:steelblock"}, {["x"] = 2, ["y"] = 7, ["param1"] = 15, ["z"] = 30, ["name"] = "default:steelblock"}, {["x"] = 2, ["y"] = 7, ["param1"] = 15, ["z"] = 31, ["name"] = "default:steelblock"}, {["x"] = 2, ["y"] = 7, ["param1"] = 15, ["z"] = 32, ["name"] = "default:steelblock"}, {["x"] = 2, ["y"] = 7, ["param1"] = 15, ["z"] = 33, ["name"] = "default:steelblock"}, {["x"] = 2, ["param2"] = 1, ["y"] = 7, ["param1"] = 206, ["z"] = 34, ["name"] = "xpanes:pane_flat"}, {["x"] = 2, ["param2"] = 3, ["y"] = 7, ["param1"] = 206, ["z"] = 35, ["name"] = "xpanes:pane_flat"}, {["x"] = 2, ["y"] = 7, ["param1"] = 15, ["z"] = 36, ["name"] = "default:steelblock"}, {["x"] = 2, ["y"] = 7, ["param1"] = 15, ["z"] = 37, ["name"] = "default:steelblock"}, {["x"] = 2, ["param2"] = 1, ["y"] = 7, ["param1"] = 206, ["z"] = 38, ["name"] = "xpanes:pane_flat"}, {["x"] = 2, ["param2"] = 3, ["y"] = 7, ["param1"] = 206, ["z"] = 39, ["name"] = "xpanes:pane_flat"}, {["x"] = 2, ["y"] = 7, ["param1"] = 15, ["z"] = 40, ["name"] = "default:steelblock"}, {["x"] = 2, ["y"] = 7, ["param1"] = 15, ["z"] = 41, ["name"] = "default:steelblock"}, {["x"] = 2, ["y"] = 7, ["param1"] = 15, ["z"] = 42, ["name"] = "default:steelblock"}, {["x"] = 2, ["y"] = 7, ["param1"] = 15, ["z"] = 45, ["name"] = "default:steelblock"}, {["x"] = 2, ["y"] = 7, ["param1"] = 15, ["z"] = 46, ["name"] = "default:steelblock"}, {["x"] = 2, ["y"] = 7, ["param1"] = 15, ["z"] = 47, ["name"] = "default:steelblock"}, {["x"] = 2, ["y"] = 7, ["param1"] = 15, ["z"] = 50, ["name"] = "default:steelblock"}, {["x"] = 2, ["y"] = 7, ["param1"] = 15, ["z"] = 51, ["name"] = "default:steelblock"}, {["x"] = 2, ["y"] = 7, ["param1"] = 15, ["z"] = 52, ["name"] = "default:steelblock"}, {["x"] = 2, ["y"] = 8, ["param1"] = 15, ["z"] = 3, ["name"] = "default:steelblock"}, {["x"] = 2, ["y"] = 8, ["param1"] = 15, ["z"] = 4, ["name"] = "default:steelblock"}, {["x"] = 2, ["y"] = 8, ["param1"] = 15, ["z"] = 5, ["name"] = "default:steelblock"}, {["x"] = 2, ["y"] = 8, ["param1"] = 15, ["z"] = 6, ["name"] = "default:steelblock"}, {["x"] = 2, ["y"] = 8, ["param1"] = 15, ["z"] = 7, ["name"] = "default:steelblock"}, {["x"] = 2, ["y"] = 8, ["param1"] = 15, ["z"] = 8, ["name"] = "default:steelblock"}, {["x"] = 2, ["y"] = 8, ["param1"] = 15, ["z"] = 9, ["name"] = "default:steelblock"}, {["x"] = 2, ["y"] = 8, ["param1"] = 15, ["z"] = 10, ["name"] = "default:steelblock"}, {["x"] = 2, ["y"] = 8, ["param1"] = 15, ["z"] = 11, ["name"] = "default:steelblock"}, {["x"] = 2, ["y"] = 8, ["param1"] = 15, ["z"] = 12, ["name"] = "default:steelblock"}, {["x"] = 2, ["y"] = 8, ["param1"] = 15, ["z"] = 13, ["name"] = "default:steelblock"}, {["x"] = 2, ["y"] = 8, ["param1"] = 15, ["z"] = 14, ["name"] = "default:steelblock"}, {["x"] = 2, ["y"] = 8, ["param1"] = 15, ["z"] = 15, ["name"] = "default:steelblock"}, {["x"] = 2, ["y"] = 8, ["param1"] = 15, ["z"] = 16, ["name"] = "default:steelblock"}, {["x"] = 2, ["y"] = 8, ["param1"] = 15, ["z"] = 17, ["name"] = "default:steelblock"}, {["x"] = 2, ["y"] = 8, ["param1"] = 15, ["z"] = 18, ["name"] = "default:steelblock"}, {["x"] = 2, ["y"] = 8, ["param1"] = 15, ["z"] = 19, ["name"] = "default:steelblock"}, {["x"] = 2, ["y"] = 8, ["param1"] = 15, ["z"] = 20, ["name"] = "default:steelblock"}, {["x"] = 2, ["y"] = 8, ["param1"] = 15, ["z"] = 21, ["name"] = "default:steelblock"}, {["x"] = 2, ["y"] = 8, ["param1"] = 15, ["z"] = 22, ["name"] = "default:steelblock"}, {["x"] = 2, ["y"] = 8, ["param1"] = 15, ["z"] = 23, ["name"] = "default:steelblock"}, {["x"] = 2, ["y"] = 8, ["param1"] = 15, ["z"] = 24, ["name"] = "default:steelblock"}, {["x"] = 2, ["y"] = 8, ["param1"] = 15, ["z"] = 25, ["name"] = "default:steelblock"}, {["x"] = 2, ["y"] = 8, ["param1"] = 15, ["z"] = 26, ["name"] = "default:steelblock"}, {["x"] = 2, ["y"] = 8, ["param1"] = 15, ["z"] = 27, ["name"] = "default:steelblock"}, {["x"] = 2, ["y"] = 8, ["param1"] = 15, ["z"] = 28, ["name"] = "default:steelblock"}, {["x"] = 2, ["y"] = 8, ["param1"] = 15, ["z"] = 29, ["name"] = "default:steelblock"}, {["x"] = 2, ["y"] = 8, ["param1"] = 15, ["z"] = 30, ["name"] = "default:steelblock"}, {["x"] = 2, ["y"] = 8, ["param1"] = 15, ["z"] = 31, ["name"] = "default:steelblock"}, {["x"] = 2, ["y"] = 8, ["param1"] = 15, ["z"] = 32, ["name"] = "default:steelblock"}, {["x"] = 2, ["y"] = 8, ["param1"] = 15, ["z"] = 33, ["name"] = "default:steelblock"}, {["x"] = 2, ["y"] = 8, ["param1"] = 15, ["z"] = 34, ["name"] = "default:steelblock"}, {["x"] = 2, ["y"] = 8, ["param1"] = 15, ["z"] = 35, ["name"] = "default:steelblock"}, {["x"] = 2, ["y"] = 8, ["param1"] = 15, ["z"] = 36, ["name"] = "default:steelblock"}, {["x"] = 2, ["y"] = 8, ["param1"] = 15, ["z"] = 37, ["name"] = "default:steelblock"}, {["x"] = 2, ["y"] = 8, ["param1"] = 15, ["z"] = 38, ["name"] = "default:steelblock"}, {["x"] = 2, ["y"] = 8, ["param1"] = 15, ["z"] = 39, ["name"] = "default:steelblock"}, {["x"] = 2, ["y"] = 8, ["param1"] = 15, ["z"] = 40, ["name"] = "default:steelblock"}, {["x"] = 2, ["y"] = 8, ["param1"] = 15, ["z"] = 41, ["name"] = "default:steelblock"}, {["x"] = 2, ["y"] = 8, ["param1"] = 15, ["z"] = 42, ["name"] = "default:steelblock"}, {["x"] = 2, ["y"] = 8, ["param1"] = 15, ["z"] = 45, ["name"] = "default:steelblock"}, {["x"] = 2, ["y"] = 8, ["param1"] = 15, ["z"] = 46, ["name"] = "default:steelblock"}, {["x"] = 2, ["y"] = 8, ["param1"] = 15, ["z"] = 47, ["name"] = "default:steelblock"}, {["x"] = 2, ["y"] = 8, ["param1"] = 15, ["z"] = 50, ["name"] = "default:steelblock"}, {["x"] = 2, ["y"] = 8, ["param1"] = 15, ["z"] = 51, ["name"] = "default:steelblock"}, {["x"] = 2, ["y"] = 8, ["param1"] = 15, ["z"] = 52, ["name"] = "default:steelblock"}, {["x"] = 2, ["y"] = 9, ["param1"] = 15, ["z"] = 3, ["name"] = "default:steelblock"}, {["x"] = 2, ["y"] = 9, ["param1"] = 15, ["z"] = 4, ["name"] = "default:steelblock"}, {["x"] = 2, ["y"] = 9, ["param1"] = 15, ["z"] = 5, ["name"] = "default:steelblock"}, {["x"] = 2, ["y"] = 9, ["param1"] = 15, ["z"] = 6, ["name"] = "default:steelblock"}, {["x"] = 2, ["y"] = 9, ["param1"] = 15, ["z"] = 7, ["name"] = "default:steelblock"}, {["x"] = 2, ["y"] = 9, ["param1"] = 15, ["z"] = 8, ["name"] = "default:steelblock"}, {["x"] = 2, ["y"] = 9, ["param1"] = 15, ["z"] = 9, ["name"] = "default:steelblock"}, {["x"] = 2, ["y"] = 9, ["param1"] = 15, ["z"] = 10, ["name"] = "default:steelblock"}, {["x"] = 2, ["y"] = 9, ["param1"] = 15, ["z"] = 11, ["name"] = "default:steelblock"}, {["x"] = 2, ["y"] = 9, ["param1"] = 15, ["z"] = 12, ["name"] = "default:steelblock"}, {["x"] = 2, ["y"] = 9, ["param1"] = 15, ["z"] = 13, ["name"] = "default:steelblock"}, {["x"] = 2, ["y"] = 9, ["param1"] = 15, ["z"] = 14, ["name"] = "default:steelblock"}, {["x"] = 2, ["y"] = 9, ["param1"] = 15, ["z"] = 15, ["name"] = "default:steelblock"}, {["x"] = 2, ["y"] = 9, ["param1"] = 15, ["z"] = 16, ["name"] = "default:steelblock"}, {["x"] = 2, ["y"] = 9, ["param1"] = 15, ["z"] = 17, ["name"] = "default:steelblock"}, {["x"] = 2, ["y"] = 9, ["param1"] = 15, ["z"] = 18, ["name"] = "default:steelblock"}, {["x"] = 2, ["y"] = 9, ["param1"] = 15, ["z"] = 19, ["name"] = "default:steelblock"}, {["x"] = 2, ["y"] = 9, ["param1"] = 15, ["z"] = 20, ["name"] = "default:steelblock"}, {["x"] = 2, ["y"] = 9, ["param1"] = 15, ["z"] = 21, ["name"] = "default:steelblock"}, {["x"] = 2, ["y"] = 9, ["param1"] = 15, ["z"] = 22, ["name"] = "default:steelblock"}, {["x"] = 2, ["y"] = 9, ["param1"] = 15, ["z"] = 23, ["name"] = "default:steelblock"}, {["x"] = 2, ["y"] = 9, ["param1"] = 15, ["z"] = 24, ["name"] = "default:steelblock"}, {["x"] = 2, ["y"] = 9, ["param1"] = 15, ["z"] = 25, ["name"] = "default:steelblock"}, {["x"] = 2, ["y"] = 9, ["param1"] = 15, ["z"] = 26, ["name"] = "default:steelblock"}, {["x"] = 2, ["y"] = 9, ["param1"] = 15, ["z"] = 27, ["name"] = "default:steelblock"}, {["x"] = 2, ["y"] = 9, ["param1"] = 15, ["z"] = 28, ["name"] = "default:steelblock"}, {["x"] = 2, ["y"] = 9, ["param1"] = 15, ["z"] = 29, ["name"] = "default:steelblock"}, {["x"] = 2, ["y"] = 9, ["param1"] = 15, ["z"] = 30, ["name"] = "default:steelblock"}, {["x"] = 2, ["y"] = 9, ["param1"] = 15, ["z"] = 31, ["name"] = "default:steelblock"}, {["x"] = 2, ["y"] = 9, ["param1"] = 15, ["z"] = 32, ["name"] = "default:steelblock"}, {["x"] = 2, ["y"] = 9, ["param1"] = 15, ["z"] = 33, ["name"] = "default:steelblock"}, {["x"] = 2, ["y"] = 9, ["param1"] = 15, ["z"] = 34, ["name"] = "default:steelblock"}, {["x"] = 2, ["y"] = 9, ["z"] = 35, ["name"] = "default:steelblock"}, {["x"] = 2, ["y"] = 9, ["param1"] = 15, ["z"] = 36, ["name"] = "default:steelblock"}, {["x"] = 2, ["y"] = 9, ["param1"] = 15, ["z"] = 37, ["name"] = "default:steelblock"}, {["x"] = 2, ["y"] = 9, ["param1"] = 15, ["z"] = 38, ["name"] = "default:steelblock"}, {["x"] = 2, ["y"] = 9, ["param1"] = 15, ["z"] = 39, ["name"] = "default:steelblock"}, {["x"] = 2, ["y"] = 9, ["param1"] = 15, ["z"] = 40, ["name"] = "default:steelblock"}, {["x"] = 2, ["y"] = 9, ["param1"] = 15, ["z"] = 41, ["name"] = "default:steelblock"}, {["x"] = 2, ["y"] = 9, ["param1"] = 15, ["z"] = 42, ["name"] = "default:steelblock"}, {["x"] = 2, ["y"] = 9, ["param1"] = 15, ["z"] = 45, ["name"] = "default:steelblock"}, {["x"] = 2, ["y"] = 9, ["param1"] = 15, ["z"] = 46, ["name"] = "default:steelblock"}, {["x"] = 2, ["y"] = 9, ["param1"] = 15, ["z"] = 47, ["name"] = "default:steelblock"}, {["x"] = 2, ["y"] = 9, ["param1"] = 15, ["z"] = 50, ["name"] = "default:steelblock"}, {["x"] = 2, ["y"] = 9, ["param1"] = 15, ["z"] = 51, ["name"] = "default:steelblock"}, {["x"] = 2, ["y"] = 9, ["param1"] = 15, ["z"] = 52, ["name"] = "default:steelblock"}, {["x"] = 2, ["y"] = 10, ["param1"] = 15, ["z"] = 3, ["name"] = "default:steelblock"}, {["x"] = 2, ["y"] = 10, ["param1"] = 15, ["z"] = 4, ["name"] = "default:steelblock"}, {["x"] = 2, ["y"] = 10, ["param1"] = 15, ["z"] = 5, ["name"] = "default:steelblock"}, {["x"] = 2, ["param2"] = 1, ["y"] = 10, ["param1"] = 190, ["z"] = 6, ["name"] = "xpanes:pane_flat"}, {["x"] = 2, ["param2"] = 3, ["y"] = 10, ["param1"] = 174, ["z"] = 7, ["name"] = "xpanes:pane_flat"}, {["x"] = 2, ["param2"] = 3, ["y"] = 10, ["param1"] = 174, ["z"] = 8, ["name"] = "xpanes:pane_flat"}, {["x"] = 2, ["param2"] = 3, ["y"] = 10, ["param1"] = 190, ["z"] = 9, ["name"] = "xpanes:pane_flat"}, {["x"] = 2, ["param2"] = 3, ["y"] = 10, ["param1"] = 174, ["z"] = 10, ["name"] = "xpanes:pane_flat"}, {["x"] = 2, ["param2"] = 3, ["y"] = 10, ["param1"] = 174, ["z"] = 11, ["name"] = "xpanes:pane_flat"}, {["x"] = 2, ["param2"] = 3, ["y"] = 10, ["param1"] = 190, ["z"] = 12, ["name"] = "xpanes:pane_flat"}, {["x"] = 2, ["param2"] = 3, ["y"] = 10, ["param1"] = 174, ["z"] = 13, ["name"] = "xpanes:pane_flat"}, {["x"] = 2, ["param2"] = 3, ["y"] = 10, ["param1"] = 174, ["z"] = 14, ["name"] = "xpanes:pane_flat"}, {["x"] = 2, ["y"] = 10, ["param1"] = 15, ["z"] = 15, ["name"] = "default:steelblock"}, {["x"] = 2, ["y"] = 10, ["param1"] = 15, ["z"] = 16, ["name"] = "default:steelblock"}, {["x"] = 2, ["y"] = 10, ["param1"] = 15, ["z"] = 17, ["name"] = "default:steelblock"}, {["x"] = 2, ["y"] = 10, ["param1"] = 15, ["z"] = 18, ["name"] = "default:steelblock"}, {["x"] = 2, ["y"] = 10, ["param1"] = 15, ["z"] = 19, ["name"] = "default:steelblock"}, {["x"] = 2, ["param2"] = 1, ["y"] = 10, ["param1"] = 174, ["z"] = 20, ["name"] = "xpanes:pane_flat"}, {["x"] = 2, ["param2"] = 3, ["y"] = 10, ["param1"] = 190, ["z"] = 21, ["name"] = "xpanes:pane_flat"}, {["x"] = 2, ["param2"] = 3, ["y"] = 10, ["param1"] = 174, ["z"] = 22, ["name"] = "xpanes:pane_flat"}, {["x"] = 2, ["param2"] = 3, ["y"] = 10, ["param1"] = 174, ["z"] = 23, ["name"] = "xpanes:pane_flat"}, {["x"] = 2, ["param2"] = 3, ["y"] = 10, ["param1"] = 190, ["z"] = 24, ["name"] = "xpanes:pane_flat"}, {["x"] = 2, ["param2"] = 3, ["y"] = 10, ["param1"] = 174, ["z"] = 25, ["name"] = "xpanes:pane_flat"}, {["x"] = 2, ["param2"] = 3, ["y"] = 10, ["param1"] = 174, ["z"] = 26, ["name"] = "xpanes:pane_flat"}, {["x"] = 2, ["param2"] = 3, ["y"] = 10, ["param1"] = 190, ["z"] = 27, ["name"] = "xpanes:pane_flat"}, {["x"] = 2, ["param2"] = 3, ["y"] = 10, ["param1"] = 174, ["z"] = 28, ["name"] = "xpanes:pane_flat"}, {["x"] = 2, ["y"] = 10, ["param1"] = 15, ["z"] = 29, ["name"] = "default:steelblock"}, {["x"] = 2, ["y"] = 10, ["param1"] = 15, ["z"] = 30, ["name"] = "default:steelblock"}, {["x"] = 2, ["y"] = 10, ["param1"] = 15, ["z"] = 31, ["name"] = "default:steelblock"}, {["x"] = 2, ["y"] = 10, ["param1"] = 15, ["z"] = 32, ["name"] = "default:steelblock"}, {["x"] = 2, ["y"] = 10, ["param1"] = 15, ["z"] = 33, ["name"] = "default:steelblock"}, {["x"] = 2, ["param2"] = 1, ["y"] = 10, ["param1"] = 158, ["z"] = 34, ["name"] = "xpanes:pane_flat"}, {["x"] = 2, ["param2"] = 3, ["y"] = 10, ["param1"] = 158, ["z"] = 35, ["name"] = "xpanes:pane_flat"}, {["x"] = 2, ["y"] = 10, ["param1"] = 15, ["z"] = 36, ["name"] = "default:steelblock"}, {["x"] = 2, ["y"] = 10, ["param1"] = 15, ["z"] = 37, ["name"] = "default:steelblock"}, {["x"] = 2, ["param2"] = 1, ["y"] = 10, ["param1"] = 158, ["z"] = 38, ["name"] = "xpanes:pane_flat"}, {["x"] = 2, ["param2"] = 3, ["y"] = 10, ["param1"] = 158, ["z"] = 39, ["name"] = "xpanes:pane_flat"}, {["x"] = 2, ["y"] = 10, ["param1"] = 15, ["z"] = 40, ["name"] = "default:steelblock"}, {["x"] = 2, ["y"] = 10, ["param1"] = 15, ["z"] = 41, ["name"] = "default:steelblock"}, {["x"] = 2, ["y"] = 10, ["param1"] = 15, ["z"] = 42, ["name"] = "default:steelblock"}, {["x"] = 2, ["y"] = 10, ["param1"] = 15, ["z"] = 45, ["name"] = "default:steelblock"}, {["x"] = 2, ["y"] = 10, ["param1"] = 15, ["z"] = 46, ["name"] = "default:steelblock"}, {["x"] = 2, ["y"] = 10, ["param1"] = 15, ["z"] = 47, ["name"] = "default:steelblock"}, {["x"] = 2, ["y"] = 10, ["param1"] = 15, ["z"] = 50, ["name"] = "default:steelblock"}, {["x"] = 2, ["y"] = 10, ["param1"] = 15, ["z"] = 51, ["name"] = "default:steelblock"}, {["x"] = 2, ["y"] = 10, ["param1"] = 15, ["z"] = 52, ["name"] = "default:steelblock"}, {["x"] = 2, ["y"] = 11, ["z"] = 2, ["name"] = "default:steelblock"}, {["x"] = 2, ["y"] = 11, ["param1"] = 15, ["z"] = 3, ["name"] = "default:steelblock"}, {["x"] = 2, ["y"] = 11, ["param1"] = 15, ["z"] = 4, ["name"] = "default:steelblock"}, {["x"] = 2, ["y"] = 11, ["param1"] = 15, ["z"] = 5, ["name"] = "default:steelblock"}, {["x"] = 2, ["y"] = 11, ["param1"] = 15, ["z"] = 6, ["name"] = "default:steelblock"}, {["x"] = 2, ["y"] = 11, ["param1"] = 15, ["z"] = 7, ["name"] = "default:steelblock"}, {["x"] = 2, ["y"] = 11, ["param1"] = 15, ["z"] = 8, ["name"] = "default:steelblock"}, {["x"] = 2, ["y"] = 11, ["param1"] = 15, ["z"] = 9, ["name"] = "default:steelblock"}, {["x"] = 2, ["y"] = 11, ["param1"] = 15, ["z"] = 10, ["name"] = "default:steelblock"}, {["x"] = 2, ["y"] = 11, ["param1"] = 15, ["z"] = 11, ["name"] = "default:steelblock"}, {["x"] = 2, ["y"] = 11, ["param1"] = 15, ["z"] = 12, ["name"] = "default:steelblock"}, {["x"] = 2, ["y"] = 11, ["param1"] = 15, ["z"] = 13, ["name"] = "default:steelblock"}, {["x"] = 2, ["y"] = 11, ["param1"] = 15, ["z"] = 14, ["name"] = "default:steelblock"}, {["x"] = 2, ["y"] = 11, ["param1"] = 15, ["z"] = 15, ["name"] = "default:steelblock"}, {["x"] = 2, ["y"] = 11, ["param1"] = 15, ["z"] = 16, ["name"] = "default:steelblock"}, {["x"] = 2, ["y"] = 11, ["param1"] = 15, ["z"] = 17, ["name"] = "default:steelblock"}, {["x"] = 2, ["y"] = 11, ["param1"] = 15, ["z"] = 18, ["name"] = "default:steelblock"}, {["x"] = 2, ["y"] = 11, ["param1"] = 15, ["z"] = 19, ["name"] = "default:steelblock"}, {["x"] = 2, ["y"] = 11, ["param1"] = 15, ["z"] = 20, ["name"] = "default:steelblock"}, {["x"] = 2, ["y"] = 11, ["param1"] = 15, ["z"] = 21, ["name"] = "default:steelblock"}, {["x"] = 2, ["y"] = 11, ["param1"] = 15, ["z"] = 22, ["name"] = "default:steelblock"}, {["x"] = 2, ["y"] = 11, ["param1"] = 15, ["z"] = 23, ["name"] = "default:steelblock"}, {["x"] = 2, ["y"] = 11, ["param1"] = 15, ["z"] = 24, ["name"] = "default:steelblock"}, {["x"] = 2, ["y"] = 11, ["param1"] = 15, ["z"] = 25, ["name"] = "default:steelblock"}, {["x"] = 2, ["y"] = 11, ["param1"] = 15, ["z"] = 26, ["name"] = "default:steelblock"}, {["x"] = 2, ["y"] = 11, ["param1"] = 15, ["z"] = 27, ["name"] = "default:steelblock"}, {["x"] = 2, ["y"] = 11, ["param1"] = 15, ["z"] = 28, ["name"] = "default:steelblock"}, {["x"] = 2, ["y"] = 11, ["param1"] = 15, ["z"] = 29, ["name"] = "default:steelblock"}, {["x"] = 2, ["y"] = 11, ["param1"] = 15, ["z"] = 30, ["name"] = "default:steelblock"}, {["x"] = 2, ["y"] = 11, ["param1"] = 15, ["z"] = 31, ["name"] = "default:steelblock"}, {["x"] = 2, ["y"] = 11, ["param1"] = 15, ["z"] = 32, ["name"] = "default:steelblock"}, {["x"] = 2, ["y"] = 11, ["param1"] = 15, ["z"] = 33, ["name"] = "default:steelblock"}, {["x"] = 2, ["y"] = 11, ["param1"] = 15, ["z"] = 34, ["name"] = "default:steelblock"}, {["x"] = 2, ["y"] = 11, ["param1"] = 15, ["z"] = 35, ["name"] = "default:steelblock"}, {["x"] = 2, ["y"] = 11, ["param1"] = 15, ["z"] = 36, ["name"] = "default:steelblock"}, {["x"] = 2, ["y"] = 11, ["param1"] = 15, ["z"] = 37, ["name"] = "default:steelblock"}, {["x"] = 2, ["y"] = 11, ["param1"] = 15, ["z"] = 38, ["name"] = "default:steelblock"}, {["x"] = 2, ["y"] = 11, ["param1"] = 15, ["z"] = 39, ["name"] = "default:steelblock"}, {["x"] = 2, ["y"] = 11, ["param1"] = 15, ["z"] = 40, ["name"] = "default:steelblock"}, {["x"] = 2, ["y"] = 11, ["param1"] = 15, ["z"] = 41, ["name"] = "default:steelblock"}, {["x"] = 2, ["y"] = 11, ["param1"] = 15, ["z"] = 42, ["name"] = "default:steelblock"}, {["x"] = 2, ["y"] = 11, ["param1"] = 15, ["z"] = 45, ["name"] = "default:steelblock"}, {["x"] = 2, ["y"] = 11, ["param1"] = 15, ["z"] = 46, ["name"] = "default:steelblock"}, {["x"] = 2, ["y"] = 11, ["param1"] = 15, ["z"] = 47, ["name"] = "default:steelblock"}, {["x"] = 2, ["y"] = 11, ["param1"] = 15, ["z"] = 50, ["name"] = "default:steelblock"}, {["x"] = 2, ["y"] = 11, ["param1"] = 15, ["z"] = 51, ["name"] = "default:steelblock"}, {["x"] = 2, ["y"] = 11, ["param1"] = 15, ["z"] = 52, ["name"] = "default:steelblock"}, {["x"] = 2, ["y"] = 11, ["z"] = 53, ["name"] = "default:steelblock"}, {["x"] = 2, ["y"] = 12, ["param1"] = 15, ["z"] = 3, ["name"] = "default:steelblock"}, {["x"] = 2, ["y"] = 12, ["param1"] = 15, ["z"] = 4, ["name"] = "default:steelblock"}, {["x"] = 2, ["y"] = 12, ["param1"] = 15, ["z"] = 5, ["name"] = "default:steelblock"}, {["x"] = 2, ["y"] = 12, ["param1"] = 15, ["z"] = 6, ["name"] = "default:steelblock"}, {["x"] = 2, ["y"] = 12, ["param1"] = 15, ["z"] = 7, ["name"] = "default:steelblock"}, {["x"] = 2, ["y"] = 12, ["param1"] = 15, ["z"] = 8, ["name"] = "default:steelblock"}, {["x"] = 2, ["y"] = 12, ["param1"] = 15, ["z"] = 9, ["name"] = "default:steelblock"}, {["x"] = 2, ["y"] = 12, ["param1"] = 15, ["z"] = 10, ["name"] = "default:steelblock"}, {["x"] = 2, ["y"] = 12, ["param1"] = 15, ["z"] = 11, ["name"] = "default:steelblock"}, {["x"] = 2, ["y"] = 12, ["param1"] = 15, ["z"] = 12, ["name"] = "default:steelblock"}, {["x"] = 2, ["y"] = 12, ["param1"] = 15, ["z"] = 13, ["name"] = "default:steelblock"}, {["x"] = 2, ["y"] = 12, ["param1"] = 15, ["z"] = 14, ["name"] = "default:steelblock"}, {["x"] = 2, ["y"] = 12, ["param1"] = 15, ["z"] = 15, ["name"] = "default:steelblock"}, {["x"] = 2, ["y"] = 12, ["param1"] = 15, ["z"] = 16, ["name"] = "default:steelblock"}, {["x"] = 2, ["y"] = 12, ["param1"] = 15, ["z"] = 17, ["name"] = "default:steelblock"}, {["x"] = 2, ["y"] = 12, ["param1"] = 15, ["z"] = 18, ["name"] = "default:steelblock"}, {["x"] = 2, ["y"] = 12, ["param1"] = 15, ["z"] = 19, ["name"] = "default:steelblock"}, {["x"] = 2, ["y"] = 12, ["param1"] = 15, ["z"] = 20, ["name"] = "default:steelblock"}, {["x"] = 2, ["y"] = 12, ["z"] = 21, ["name"] = "default:steelblock"}, {["x"] = 2, ["y"] = 12, ["param1"] = 15, ["z"] = 22, ["name"] = "default:steelblock"}, {["x"] = 2, ["y"] = 12, ["param1"] = 15, ["z"] = 23, ["name"] = "default:steelblock"}, {["x"] = 2, ["y"] = 12, ["param1"] = 15, ["z"] = 24, ["name"] = "default:steelblock"}, {["x"] = 2, ["y"] = 12, ["param1"] = 15, ["z"] = 25, ["name"] = "default:steelblock"}, {["x"] = 2, ["y"] = 12, ["param1"] = 15, ["z"] = 26, ["name"] = "default:steelblock"}, {["x"] = 2, ["y"] = 12, ["param1"] = 15, ["z"] = 27, ["name"] = "default:steelblock"}, {["x"] = 2, ["y"] = 12, ["param1"] = 15, ["z"] = 28, ["name"] = "default:steelblock"}, {["x"] = 2, ["y"] = 12, ["param1"] = 15, ["z"] = 29, ["name"] = "default:steelblock"}, {["x"] = 2, ["y"] = 12, ["param1"] = 15, ["z"] = 30, ["name"] = "default:steelblock"}, {["x"] = 2, ["y"] = 12, ["param1"] = 15, ["z"] = 31, ["name"] = "default:steelblock"}, {["x"] = 2, ["y"] = 12, ["param1"] = 15, ["z"] = 32, ["name"] = "default:steelblock"}, {["x"] = 2, ["y"] = 12, ["param1"] = 15, ["z"] = 33, ["name"] = "default:steelblock"}, {["x"] = 2, ["y"] = 12, ["param1"] = 15, ["z"] = 34, ["name"] = "default:steelblock"}, {["x"] = 2, ["y"] = 12, ["param1"] = 15, ["z"] = 35, ["name"] = "default:steelblock"}, {["x"] = 2, ["y"] = 12, ["param1"] = 15, ["z"] = 36, ["name"] = "default:steelblock"}, {["x"] = 2, ["y"] = 12, ["param1"] = 15, ["z"] = 37, ["name"] = "default:steelblock"}, {["x"] = 2, ["y"] = 12, ["param1"] = 15, ["z"] = 38, ["name"] = "default:steelblock"}, {["x"] = 2, ["y"] = 12, ["param1"] = 15, ["z"] = 39, ["name"] = "default:steelblock"}, {["x"] = 2, ["y"] = 12, ["param1"] = 15, ["z"] = 40, ["name"] = "default:steelblock"}, {["x"] = 2, ["y"] = 12, ["param1"] = 15, ["z"] = 41, ["name"] = "default:steelblock"}, {["x"] = 2, ["y"] = 12, ["param1"] = 15, ["z"] = 42, ["name"] = "default:steelblock"}, {["x"] = 2, ["y"] = 12, ["z"] = 43, ["name"] = "default:steelblock"}, {["x"] = 2, ["y"] = 12, ["z"] = 44, ["name"] = "default:steelblock"}, {["x"] = 2, ["y"] = 12, ["param1"] = 15, ["z"] = 45, ["name"] = "default:steelblock"}, {["x"] = 2, ["y"] = 12, ["param1"] = 15, ["z"] = 46, ["name"] = "default:steelblock"}, {["x"] = 2, ["y"] = 12, ["param1"] = 15, ["z"] = 47, ["name"] = "default:steelblock"}, {["x"] = 2, ["y"] = 12, ["z"] = 48, ["name"] = "default:steelblock"}, {["x"] = 2, ["y"] = 12, ["z"] = 49, ["name"] = "default:steelblock"}, {["x"] = 2, ["y"] = 12, ["param1"] = 15, ["z"] = 50, ["name"] = "default:steelblock"}, {["x"] = 2, ["y"] = 12, ["param1"] = 15, ["z"] = 51, ["name"] = "default:steelblock"}, {["x"] = 2, ["y"] = 12, ["param1"] = 15, ["z"] = 52, ["name"] = "default:steelblock"}, {["x"] = 3, ["y"] = 0, ["param1"] = 46, ["z"] = 2, ["name"] = "stairs:stair_steelblock"}, {["x"] = 3, ["y"] = 0, ["param1"] = 15, ["z"] = 3, ["name"] = "default:steelblock"}, {["x"] = 3, ["y"] = 0, ["param1"] = 15, ["z"] = 4, ["name"] = "default:steelblock"}, {["x"] = 3, ["y"] = 0, ["param1"] = 15, ["z"] = 5, ["name"] = "default:steelblock"}, {["x"] = 3, ["y"] = 0, ["param1"] = 15, ["z"] = 6, ["name"] = "default:steelblock"}, {["x"] = 3, ["y"] = 0, ["param1"] = 15, ["z"] = 7, ["name"] = "default:steelblock"}, {["x"] = 3, ["y"] = 0, ["param1"] = 15, ["z"] = 8, ["name"] = "default:steelblock"}, {["x"] = 3, ["y"] = 0, ["param1"] = 15, ["z"] = 9, ["name"] = "default:steelblock"}, {["x"] = 3, ["y"] = 0, ["param1"] = 15, ["z"] = 10, ["name"] = "default:steelblock"}, {["x"] = 3, ["y"] = 0, ["param1"] = 15, ["z"] = 11, ["name"] = "default:steelblock"}, {["x"] = 3, ["y"] = 0, ["param1"] = 15, ["z"] = 12, ["name"] = "default:steelblock"}, {["x"] = 3, ["y"] = 0, ["param1"] = 15, ["z"] = 13, ["name"] = "default:steelblock"}, {["x"] = 3, ["y"] = 0, ["param1"] = 15, ["z"] = 14, ["name"] = "default:steelblock"}, {["x"] = 3, ["y"] = 0, ["param1"] = 15, ["z"] = 15, ["name"] = "default:steelblock"}, {["x"] = 3, ["y"] = 0, ["param1"] = 15, ["z"] = 16, ["name"] = "default:steelblock"}, {["x"] = 3, ["y"] = 0, ["param1"] = 15, ["z"] = 17, ["name"] = "default:steelblock"}, {["x"] = 3, ["y"] = 0, ["param1"] = 15, ["z"] = 18, ["name"] = "default:steelblock"}, {["x"] = 3, ["y"] = 0, ["param1"] = 15, ["z"] = 19, ["name"] = "default:steelblock"}, {["x"] = 3, ["y"] = 0, ["param1"] = 15, ["z"] = 20, ["name"] = "default:steelblock"}, {["x"] = 3, ["y"] = 0, ["param1"] = 15, ["z"] = 21, ["name"] = "default:steelblock"}, {["x"] = 3, ["y"] = 0, ["param1"] = 15, ["z"] = 22, ["name"] = "default:steelblock"}, {["x"] = 3, ["y"] = 0, ["param1"] = 15, ["z"] = 23, ["name"] = "default:steelblock"}, {["x"] = 3, ["y"] = 0, ["param1"] = 15, ["z"] = 24, ["name"] = "default:steelblock"}, {["x"] = 3, ["y"] = 0, ["param1"] = 15, ["z"] = 25, ["name"] = "default:steelblock"}, {["x"] = 3, ["y"] = 0, ["param1"] = 15, ["z"] = 26, ["name"] = "default:steelblock"}, {["x"] = 3, ["y"] = 0, ["param1"] = 15, ["z"] = 27, ["name"] = "default:steelblock"}, {["x"] = 3, ["y"] = 0, ["param1"] = 15, ["z"] = 28, ["name"] = "default:steelblock"}, {["x"] = 3, ["y"] = 0, ["param1"] = 15, ["z"] = 29, ["name"] = "default:steelblock"}, {["x"] = 3, ["y"] = 0, ["param1"] = 15, ["z"] = 30, ["name"] = "default:steelblock"}, {["x"] = 3, ["y"] = 0, ["param1"] = 15, ["z"] = 31, ["name"] = "default:steelblock"}, {["x"] = 3, ["y"] = 0, ["param1"] = 15, ["z"] = 32, ["name"] = "default:steelblock"}, {["x"] = 3, ["y"] = 0, ["param1"] = 15, ["z"] = 33, ["name"] = "default:steelblock"}, {["x"] = 3, ["y"] = 0, ["param1"] = 15, ["z"] = 34, ["name"] = "default:steelblock"}, {["x"] = 3, ["y"] = 0, ["param1"] = 15, ["z"] = 35, ["name"] = "default:steelblock"}, {["x"] = 3, ["y"] = 0, ["param1"] = 15, ["z"] = 36, ["name"] = "default:steelblock"}, {["x"] = 3, ["y"] = 0, ["param1"] = 15, ["z"] = 37, ["name"] = "default:steelblock"}, {["x"] = 3, ["y"] = 0, ["param1"] = 15, ["z"] = 38, ["name"] = "default:steelblock"}, {["x"] = 3, ["y"] = 0, ["param1"] = 15, ["z"] = 39, ["name"] = "default:steelblock"}, {["x"] = 3, ["y"] = 0, ["param1"] = 15, ["z"] = 40, ["name"] = "default:steelblock"}, {["x"] = 3, ["y"] = 0, ["param1"] = 15, ["z"] = 41, ["name"] = "default:steelblock"}, {["x"] = 3, ["y"] = 0, ["param1"] = 15, ["z"] = 42, ["name"] = "default:steelblock"}, {["x"] = 3, ["y"] = 0, ["param1"] = 15, ["z"] = 43, ["name"] = "default:steelblock"}, {["x"] = 3, ["y"] = 0, ["param1"] = 15, ["z"] = 44, ["name"] = "default:steelblock"}, {["x"] = 3, ["y"] = 0, ["param1"] = 15, ["z"] = 45, ["name"] = "default:steelblock"}, {["x"] = 3, ["y"] = 0, ["param1"] = 15, ["z"] = 46, ["name"] = "default:steelblock"}, {["x"] = 3, ["y"] = 0, ["param1"] = 15, ["z"] = 47, ["name"] = "default:steelblock"}, {["x"] = 3, ["y"] = 0, ["param1"] = 15, ["z"] = 48, ["name"] = "default:steelblock"}, {["x"] = 3, ["y"] = 0, ["param1"] = 15, ["z"] = 49, ["name"] = "default:steelblock"}, {["x"] = 3, ["y"] = 0, ["param1"] = 15, ["z"] = 50, ["name"] = "default:steelblock"}, {["x"] = 3, ["y"] = 0, ["param1"] = 15, ["z"] = 51, ["name"] = "default:steelblock"}, {["x"] = 3, ["y"] = 0, ["param1"] = 15, ["z"] = 52, ["name"] = "default:steelblock"}, {["x"] = 3, ["param2"] = 2, ["y"] = 0, ["param1"] = 14, ["z"] = 53, ["name"] = "stairs:stair_steelblock"}, {["x"] = 3, ["y"] = 1, ["param1"] = 15, ["z"] = 3, ["name"] = "default:steelblock"}, {["x"] = 3, ["y"] = 1, ["param1"] = 15, ["z"] = 17, ["name"] = "default:steelblock"}, {["x"] = 3, ["y"] = 1, ["param1"] = 15, ["z"] = 31, ["name"] = "default:steelblock"}, {["x"] = 3, ["y"] = 1, ["param1"] = 142, ["z"] = 32, ["name"] = "university:lobby_table"}, {["x"] = 3, ["param2"] = 3, ["y"] = 1, ["param1"] = 158, ["z"] = 33, ["name"] = "university:lobby_table"}, {["x"] = 3, ["param2"] = 3, ["y"] = 1, ["param1"] = 158, ["z"] = 34, ["name"] = "university:lobby_table"}, {["x"] = 3, ["param2"] = 3, ["y"] = 1, ["param1"] = 158, ["z"] = 35, ["name"] = "university:lobby_table"}, {["x"] = 3, ["param2"] = 3, ["y"] = 1, ["param1"] = 158, ["z"] = 36, ["name"] = "university:lobby_table"}, {["x"] = 3, ["param2"] = 3, ["y"] = 1, ["param1"] = 158, ["z"] = 37, ["name"] = "university:lobby_table"}, {["x"] = 3, ["param2"] = 3, ["y"] = 1, ["param1"] = 158, ["z"] = 38, ["name"] = "university:lobby_table"}, {["x"] = 3, ["param2"] = 3, ["y"] = 1, ["param1"] = 158, ["z"] = 39, ["name"] = "university:lobby_table"}, {["x"] = 3, ["param2"] = 3, ["y"] = 1, ["param1"] = 142, ["z"] = 40, ["name"] = "university:lobby_table"}, {["x"] = 3, ["param2"] = 2, ["y"] = 1, ["param1"] = 158, ["z"] = 41, ["name"] = "university:lobby_table"}, {["x"] = 3, ["y"] = 1, ["param1"] = 15, ["z"] = 42, ["name"] = "default:steelblock"}, {["x"] = 3, ["y"] = 1, ["z"] = 45, ["name"] = "default:steelblock"}, {["x"] = 3, ["y"] = 1, ["z"] = 46, ["name"] = "default:steelblock"}, {["x"] = 3, ["y"] = 1, ["z"] = 47, ["name"] = "default:steelblock"}, {["x"] = 3, ["y"] = 1, ["z"] = 50, ["name"] = "default:steelblock"}, {["x"] = 3, ["y"] = 1, ["param1"] = 15, ["z"] = 51, ["name"] = "default:steelblock"}, {["x"] = 3, ["y"] = 1, ["param1"] = 15, ["z"] = 52, ["name"] = "default:steelblock"}, {["x"] = 3, ["y"] = 2, ["param1"] = 15, ["z"] = 3, ["name"] = "default:steelblock"}, {["x"] = 3, ["y"] = 2, ["param1"] = 158, ["z"] = 16, ["name"] = "university:blackboard_bottom"}, {["x"] = 3, ["y"] = 2, ["param1"] = 15, ["z"] = 17, ["name"] = "default:steelblock"}, {["x"] = 3, ["y"] = 2, ["param1"] = 158, ["z"] = 30, ["name"] = "university:blackboard_bottom"}, {["x"] = 3, ["y"] = 2, ["param1"] = 15, ["z"] = 31, ["name"] = "default:steelblock"}, {["x"] = 3, ["y"] = 2, ["param1"] = 15, ["z"] = 42, ["name"] = "default:steelblock"}, {["x"] = 3, ["y"] = 2, ["z"] = 45, ["name"] = "default:steelblock"}, {["x"] = 3, ["y"] = 2, ["z"] = 46, ["name"] = "default:steelblock"}, {["x"] = 3, ["y"] = 2, ["z"] = 47, ["name"] = "default:steelblock"}, {["x"] = 3, ["y"] = 2, ["param1"] = 15, ["z"] = 50, ["name"] = "default:steelblock"}, {["x"] = 3, ["y"] = 2, ["param1"] = 15, ["z"] = 51, ["name"] = "default:steelblock"}, {["x"] = 3, ["y"] = 2, ["param1"] = 15, ["z"] = 52, ["name"] = "default:steelblock"}, {["x"] = 3, ["y"] = 3, ["param1"] = 15, ["z"] = 3, ["name"] = "default:steelblock"}, {["x"] = 3, ["y"] = 3, ["param1"] = 174, ["z"] = 16, ["name"] = "university:blackboard_top"}, {["x"] = 3, ["y"] = 3, ["param1"] = 15, ["z"] = 17, ["name"] = "default:steelblock"}, {["x"] = 3, ["y"] = 3, ["param1"] = 174, ["z"] = 30, ["name"] = "university:blackboard_top"}, {["x"] = 3, ["y"] = 3, ["param1"] = 15, ["z"] = 31, ["name"] = "default:steelblock"}, {["x"] = 3, ["y"] = 3, ["param1"] = 15, ["z"] = 42, ["name"] = "default:steelblock"}, {["x"] = 3, ["y"] = 3, ["z"] = 45, ["name"] = "default:steelblock"}, {["x"] = 3, ["y"] = 3, ["z"] = 46, ["name"] = "default:steelblock"}, {["x"] = 3, ["y"] = 3, ["z"] = 47, ["name"] = "default:steelblock"}, {["x"] = 3, ["y"] = 3, ["param1"] = 15, ["z"] = 50, ["name"] = "default:steelblock"}, {["x"] = 3, ["y"] = 3, ["param1"] = 15, ["z"] = 51, ["name"] = "default:steelblock"}, {["x"] = 3, ["y"] = 3, ["param1"] = 15, ["z"] = 52, ["name"] = "default:steelblock"}, {["x"] = 3, ["y"] = 4, ["param1"] = 15, ["z"] = 3, ["name"] = "default:steelblock"}, {["x"] = 3, ["y"] = 4, ["param1"] = 190, ["z"] = 16, ["name"] = "university:blackboard_top"}, {["x"] = 3, ["y"] = 4, ["param1"] = 15, ["z"] = 17, ["name"] = "default:steelblock"}, {["x"] = 3, ["y"] = 4, ["param1"] = 190, ["z"] = 30, ["name"] = "university:blackboard_top"}, {["x"] = 3, ["y"] = 4, ["param1"] = 15, ["z"] = 31, ["name"] = "default:steelblock"}, {["x"] = 3, ["y"] = 4, ["param1"] = 15, ["z"] = 42, ["name"] = "default:steelblock"}, {["x"] = 3, ["y"] = 4, ["z"] = 45, ["name"] = "default:steelblock"}, {["x"] = 3, ["y"] = 4, ["z"] = 46, ["name"] = "default:steelblock"}, {["x"] = 3, ["y"] = 4, ["z"] = 47, ["name"] = "default:steelblock"}, {["x"] = 3, ["y"] = 4, ["param1"] = 15, ["z"] = 50, ["name"] = "default:steelblock"}, {["x"] = 3, ["y"] = 4, ["param1"] = 15, ["z"] = 51, ["name"] = "default:steelblock"}, {["x"] = 3, ["y"] = 4, ["param1"] = 15, ["z"] = 52, ["name"] = "default:steelblock"}, {["x"] = 3, ["y"] = 5, ["param1"] = 15, ["z"] = 3, ["name"] = "default:steelblock"}, {["x"] = 3, ["y"] = 5, ["param1"] = 206, ["z"] = 16, ["name"] = "university:blackboard_top"}, {["x"] = 3, ["y"] = 5, ["param1"] = 15, ["z"] = 17, ["name"] = "default:steelblock"}, {["x"] = 3, ["y"] = 5, ["param1"] = 206, ["z"] = 30, ["name"] = "university:blackboard_top"}, {["x"] = 3, ["y"] = 5, ["param1"] = 15, ["z"] = 31, ["name"] = "default:steelblock"}, {["x"] = 3, ["y"] = 5, ["param1"] = 15, ["z"] = 42, ["name"] = "default:steelblock"}, {["x"] = 3, ["y"] = 5, ["z"] = 45, ["name"] = "default:steelblock"}, {["x"] = 3, ["y"] = 5, ["z"] = 46, ["name"] = "default:steelblock"}, {["x"] = 3, ["y"] = 5, ["z"] = 47, ["name"] = "default:steelblock"}, {["x"] = 3, ["y"] = 5, ["param1"] = 15, ["z"] = 50, ["name"] = "default:steelblock"}, {["x"] = 3, ["y"] = 5, ["param1"] = 15, ["z"] = 51, ["name"] = "default:steelblock"}, {["x"] = 3, ["y"] = 5, ["param1"] = 15, ["z"] = 52, ["name"] = "default:steelblock"}, {["x"] = 3, ["y"] = 6, ["param1"] = 15, ["z"] = 3, ["name"] = "default:steelblock"}, {["x"] = 3, ["param2"] = 3, ["y"] = 6, ["param1"] = 239, ["z"] = 5, ["name"] = "morelights_modern:barlight_s"}, {["x"] = 3, ["param2"] = 3, ["y"] = 6, ["param1"] = 239, ["z"] = 6, ["name"] = "morelights_modern:barlight_s"}, {["x"] = 3, ["param2"] = 3, ["y"] = 6, ["param1"] = 239, ["z"] = 7, ["name"] = "morelights_modern:barlight_s"}, {["x"] = 3, ["param2"] = 3, ["y"] = 6, ["param1"] = 239, ["z"] = 8, ["name"] = "morelights_modern:barlight_s"}, {["x"] = 3, ["param2"] = 3, ["y"] = 6, ["param1"] = 239, ["z"] = 9, ["name"] = "morelights_modern:barlight_s"}, {["x"] = 3, ["param2"] = 3, ["y"] = 6, ["param1"] = 239, ["z"] = 10, ["name"] = "morelights_modern:barlight_s"}, {["x"] = 3, ["param2"] = 3, ["y"] = 6, ["param1"] = 239, ["z"] = 11, ["name"] = "morelights_modern:barlight_s"}, {["x"] = 3, ["param2"] = 3, ["y"] = 6, ["param1"] = 239, ["z"] = 12, ["name"] = "morelights_modern:barlight_s"}, {["x"] = 3, ["param2"] = 3, ["y"] = 6, ["param1"] = 239, ["z"] = 13, ["name"] = "morelights_modern:barlight_s"}, {["x"] = 3, ["y"] = 6, ["param1"] = 239, ["z"] = 15, ["name"] = "morelights_modern:barlight_s"}, {["x"] = 3, ["y"] = 6, ["param1"] = 222, ["z"] = 16, ["name"] = "university:blackboard_top"}, {["x"] = 3, ["y"] = 6, ["param1"] = 15, ["z"] = 17, ["name"] = "default:steelblock"}, {["x"] = 3, ["param2"] = 3, ["y"] = 6, ["param1"] = 239, ["z"] = 19, ["name"] = "morelights_modern:barlight_s"}, {["x"] = 3, ["param2"] = 3, ["y"] = 6, ["param1"] = 239, ["z"] = 20, ["name"] = "morelights_modern:barlight_s"}, {["x"] = 3, ["param2"] = 3, ["y"] = 6, ["param1"] = 239, ["z"] = 21, ["name"] = "morelights_modern:barlight_s"}, {["x"] = 3, ["param2"] = 3, ["y"] = 6, ["param1"] = 239, ["z"] = 22, ["name"] = "morelights_modern:barlight_s"}, {["x"] = 3, ["param2"] = 3, ["y"] = 6, ["param1"] = 239, ["z"] = 23, ["name"] = "morelights_modern:barlight_s"}, {["x"] = 3, ["param2"] = 3, ["y"] = 6, ["param1"] = 239, ["z"] = 24, ["name"] = "morelights_modern:barlight_s"}, {["x"] = 3, ["param2"] = 3, ["y"] = 6, ["param1"] = 239, ["z"] = 25, ["name"] = "morelights_modern:barlight_s"}, {["x"] = 3, ["param2"] = 3, ["y"] = 6, ["param1"] = 239, ["z"] = 26, ["name"] = "morelights_modern:barlight_s"}, {["x"] = 3, ["param2"] = 3, ["y"] = 6, ["param1"] = 239, ["z"] = 27, ["name"] = "morelights_modern:barlight_s"}, {["x"] = 3, ["y"] = 6, ["param1"] = 239, ["z"] = 29, ["name"] = "morelights_modern:barlight_s"}, {["x"] = 3, ["y"] = 6, ["param1"] = 222, ["z"] = 30, ["name"] = "university:blackboard_top"}, {["x"] = 3, ["y"] = 6, ["param1"] = 15, ["z"] = 31, ["name"] = "default:steelblock"}, {["x"] = 3, ["param2"] = 3, ["y"] = 6, ["param1"] = 239, ["z"] = 33, ["name"] = "morelights_modern:barlight_s"}, {["x"] = 3, ["param2"] = 3, ["y"] = 6, ["param1"] = 239, ["z"] = 34, ["name"] = "morelights_modern:barlight_s"}, {["x"] = 3, ["param2"] = 3, ["y"] = 6, ["param1"] = 239, ["z"] = 35, ["name"] = "morelights_modern:barlight_s"}, {["x"] = 3, ["param2"] = 3, ["y"] = 6, ["param1"] = 239, ["z"] = 36, ["name"] = "morelights_modern:barlight_s"}, {["x"] = 3, ["param2"] = 3, ["y"] = 6, ["param1"] = 239, ["z"] = 37, ["name"] = "morelights_modern:barlight_s"}, {["x"] = 3, ["param2"] = 3, ["y"] = 6, ["param1"] = 239, ["z"] = 38, ["name"] = "morelights_modern:barlight_s"}, {["x"] = 3, ["param2"] = 3, ["y"] = 6, ["param1"] = 239, ["z"] = 39, ["name"] = "morelights_modern:barlight_s"}, {["x"] = 3, ["y"] = 6, ["param1"] = 239, ["z"] = 41, ["name"] = "morelights_modern:barlight_s"}, {["x"] = 3, ["y"] = 6, ["param1"] = 15, ["z"] = 42, ["name"] = "default:steelblock"}, {["x"] = 3, ["y"] = 6, ["z"] = 45, ["name"] = "default:steelblock"}, {["x"] = 3, ["y"] = 6, ["z"] = 46, ["name"] = "default:steelblock"}, {["x"] = 3, ["y"] = 6, ["z"] = 47, ["name"] = "default:steelblock"}, {["x"] = 3, ["y"] = 6, ["param1"] = 15, ["z"] = 50, ["name"] = "default:steelblock"}, {["x"] = 3, ["y"] = 6, ["param1"] = 15, ["z"] = 51, ["name"] = "default:steelblock"}, {["x"] = 3, ["y"] = 6, ["param1"] = 15, ["z"] = 52, ["name"] = "default:steelblock"}, {["x"] = 3, ["y"] = 7, ["param1"] = 15, ["z"] = 3, ["name"] = "default:steelblock"}, {["x"] = 3, ["y"] = 7, ["param1"] = 15, ["z"] = 17, ["name"] = "default:steelblock"}, {["x"] = 3, ["y"] = 7, ["param1"] = 15, ["z"] = 31, ["name"] = "default:steelblock"}, {["x"] = 3, ["y"] = 7, ["param1"] = 15, ["z"] = 42, ["name"] = "default:steelblock"}, {["x"] = 3, ["y"] = 7, ["z"] = 45, ["name"] = "default:steelblock"}, {["x"] = 3, ["y"] = 7, ["z"] = 46, ["name"] = "default:steelblock"}, {["x"] = 3, ["y"] = 7, ["z"] = 47, ["name"] = "default:steelblock"}, {["x"] = 3, ["y"] = 7, ["param1"] = 15, ["z"] = 50, ["name"] = "default:steelblock"}, {["x"] = 3, ["y"] = 7, ["param1"] = 15, ["z"] = 51, ["name"] = "default:steelblock"}, {["x"] = 3, ["y"] = 7, ["param1"] = 15, ["z"] = 52, ["name"] = "default:steelblock"}, {["x"] = 3, ["y"] = 8, ["param1"] = 15, ["z"] = 3, ["name"] = "default:steelblock"}, {["x"] = 3, ["y"] = 8, ["param1"] = 15, ["z"] = 17, ["name"] = "default:steelblock"}, {["x"] = 3, ["y"] = 8, ["param1"] = 15, ["z"] = 31, ["name"] = "default:steelblock"}, {["x"] = 3, ["y"] = 8, ["param1"] = 15, ["z"] = 42, ["name"] = "default:steelblock"}, {["x"] = 3, ["y"] = 8, ["z"] = 45, ["name"] = "default:steelblock"}, {["x"] = 3, ["y"] = 8, ["z"] = 46, ["name"] = "default:steelblock"}, {["x"] = 3, ["y"] = 8, ["z"] = 47, ["name"] = "default:steelblock"}, {["x"] = 3, ["y"] = 8, ["param1"] = 15, ["z"] = 50, ["name"] = "default:steelblock"}, {["x"] = 3, ["y"] = 8, ["param1"] = 15, ["z"] = 51, ["name"] = "default:steelblock"}, {["x"] = 3, ["y"] = 8, ["param1"] = 15, ["z"] = 52, ["name"] = "default:steelblock"}, {["x"] = 3, ["y"] = 9, ["param1"] = 15, ["z"] = 3, ["name"] = "default:steelblock"}, {["x"] = 3, ["y"] = 9, ["param1"] = 15, ["z"] = 17, ["name"] = "default:steelblock"}, {["x"] = 3, ["y"] = 9, ["param1"] = 15, ["z"] = 31, ["name"] = "default:steelblock"}, {["x"] = 3, ["y"] = 9, ["param1"] = 15, ["z"] = 42, ["name"] = "default:steelblock"}, {["x"] = 3, ["y"] = 9, ["z"] = 45, ["name"] = "default:steelblock"}, {["x"] = 3, ["y"] = 9, ["z"] = 46, ["name"] = "default:steelblock"}, {["x"] = 3, ["y"] = 9, ["z"] = 47, ["name"] = "default:steelblock"}, {["x"] = 3, ["y"] = 9, ["param1"] = 15, ["z"] = 50, ["name"] = "default:steelblock"}, {["x"] = 3, ["y"] = 9, ["param1"] = 15, ["z"] = 51, ["name"] = "default:steelblock"}, {["x"] = 3, ["y"] = 9, ["param1"] = 15, ["z"] = 52, ["name"] = "default:steelblock"}, {["x"] = 3, ["y"] = 10, ["param1"] = 15, ["z"] = 3, ["name"] = "default:steelblock"}, {["x"] = 3, ["y"] = 10, ["param1"] = 15, ["z"] = 17, ["name"] = "default:steelblock"}, {["x"] = 3, ["y"] = 10, ["param1"] = 15, ["z"] = 31, ["name"] = "default:steelblock"}, {["x"] = 3, ["y"] = 10, ["param1"] = 15, ["z"] = 42, ["name"] = "default:steelblock"}, {["x"] = 3, ["y"] = 10, ["z"] = 45, ["name"] = "default:steelblock"}, {["x"] = 3, ["y"] = 10, ["z"] = 46, ["name"] = "default:steelblock"}, {["x"] = 3, ["y"] = 10, ["z"] = 47, ["name"] = "default:steelblock"}, {["x"] = 3, ["y"] = 10, ["param1"] = 15, ["z"] = 50, ["name"] = "default:steelblock"}, {["x"] = 3, ["y"] = 10, ["param1"] = 15, ["z"] = 51, ["name"] = "default:steelblock"}, {["x"] = 3, ["y"] = 10, ["param1"] = 15, ["z"] = 52, ["name"] = "default:steelblock"}, {["x"] = 3, ["y"] = 11, ["z"] = 2, ["name"] = "default:steelblock"}, {["x"] = 3, ["y"] = 11, ["param1"] = 15, ["z"] = 3, ["name"] = "default:steelblock"}, {["x"] = 3, ["y"] = 11, ["param1"] = 15, ["z"] = 17, ["name"] = "default:steelblock"}, {["x"] = 3, ["y"] = 11, ["param1"] = 14, ["z"] = 31, ["name"] = "default:steelblock"}, {["x"] = 3, ["y"] = 11, ["param1"] = 15, ["z"] = 42, ["name"] = "default:steelblock"}, {["x"] = 3, ["y"] = 11, ["z"] = 45, ["name"] = "default:steelblock"}, {["x"] = 3, ["y"] = 11, ["z"] = 46, ["name"] = "default:steelblock"}, {["x"] = 3, ["y"] = 11, ["z"] = 47, ["name"] = "default:steelblock"}, {["x"] = 3, ["y"] = 11, ["param1"] = 14, ["z"] = 50, ["name"] = "default:steelblock"}, {["x"] = 3, ["y"] = 11, ["param1"] = 14, ["z"] = 51, ["name"] = "default:steelblock"}, {["x"] = 3, ["y"] = 11, ["param1"] = 15, ["z"] = 52, ["name"] = "default:steelblock"}, {["x"] = 3, ["y"] = 11, ["z"] = 53, ["name"] = "default:steelblock"}, {["x"] = 3, ["y"] = 12, ["param1"] = 15, ["z"] = 3, ["name"] = "default:steelblock"}, {["x"] = 3, ["y"] = 12, ["param1"] = 238, ["z"] = 6, ["name"] = "morelights_modern:ceilinglight"}, {["x"] = 3, ["y"] = 12, ["param1"] = 238, ["z"] = 9, ["name"] = "morelights_modern:ceilinglight"}, {["x"] = 3, ["y"] = 12, ["param1"] = 238, ["z"] = 12, ["name"] = "morelights_modern:ceilinglight"}, {["x"] = 3, ["y"] = 12, ["param1"] = 238, ["z"] = 15, ["name"] = "morelights_modern:ceilinglight"}, {["x"] = 3, ["y"] = 12, ["param1"] = 238, ["z"] = 18, ["name"] = "morelights_modern:ceilinglight"}, {["x"] = 3, ["y"] = 12, ["param1"] = 238, ["z"] = 21, ["name"] = "morelights_modern:ceilinglight"}, {["x"] = 3, ["y"] = 12, ["param1"] = 238, ["z"] = 24, ["name"] = "morelights_modern:ceilinglight"}, {["x"] = 3, ["y"] = 12, ["param1"] = 238, ["z"] = 27, ["name"] = "morelights_modern:ceilinglight"}, {["x"] = 3, ["y"] = 12, ["param1"] = 238, ["z"] = 29, ["name"] = "morelights_modern:ceilinglight"}, {["x"] = 3, ["y"] = 12, ["z"] = 42, ["name"] = "default:steelblock"}, {["x"] = 3, ["y"] = 12, ["z"] = 45, ["name"] = "default:steelblock"}, {["x"] = 3, ["y"] = 12, ["z"] = 46, ["name"] = "default:steelblock"}, {["x"] = 3, ["y"] = 12, ["z"] = 47, ["name"] = "default:steelblock"}, {["x"] = 3, ["y"] = 12, ["param1"] = 14, ["z"] = 50, ["name"] = "default:steelblock"}, {["x"] = 3, ["y"] = 12, ["param1"] = 14, ["z"] = 51, ["name"] = "default:steelblock"}, {["x"] = 3, ["y"] = 12, ["param1"] = 15, ["z"] = 52, ["name"] = "default:steelblock"}, {["x"] = 3, ["y"] = 13, ["param1"] = 15, ["z"] = 3, ["name"] = "default:steelblock"}, {["x"] = 3, ["y"] = 13, ["param1"] = 15, ["z"] = 4, ["name"] = "default:steelblock"}, {["x"] = 3, ["y"] = 13, ["param1"] = 15, ["z"] = 5, ["name"] = "default:steelblock"}, {["x"] = 3, ["y"] = 13, ["param1"] = 15, ["z"] = 6, ["name"] = "default:steelblock"}, {["x"] = 3, ["y"] = 13, ["param1"] = 15, ["z"] = 7, ["name"] = "default:steelblock"}, {["x"] = 3, ["y"] = 13, ["param1"] = 15, ["z"] = 8, ["name"] = "default:steelblock"}, {["x"] = 3, ["y"] = 13, ["param1"] = 15, ["z"] = 9, ["name"] = "default:steelblock"}, {["x"] = 3, ["y"] = 13, ["param1"] = 15, ["z"] = 10, ["name"] = "default:steelblock"}, {["x"] = 3, ["y"] = 13, ["param1"] = 14, ["z"] = 11, ["name"] = "default:steelblock"}, {["x"] = 3, ["y"] = 13, ["param1"] = 14, ["z"] = 12, ["name"] = "default:steelblock"}, {["x"] = 3, ["y"] = 13, ["param1"] = 15, ["z"] = 13, ["name"] = "default:steelblock"}, {["x"] = 3, ["y"] = 13, ["param1"] = 15, ["z"] = 14, ["name"] = "default:steelblock"}, {["x"] = 3, ["y"] = 13, ["param1"] = 15, ["z"] = 15, ["name"] = "default:steelblock"}, {["x"] = 3, ["y"] = 13, ["param1"] = 15, ["z"] = 16, ["name"] = "default:steelblock"}, {["x"] = 3, ["y"] = 13, ["param1"] = 15, ["z"] = 17, ["name"] = "default:steelblock"}, {["x"] = 3, ["y"] = 13, ["param1"] = 15, ["z"] = 18, ["name"] = "default:steelblock"}, {["x"] = 3, ["y"] = 13, ["param1"] = 15, ["z"] = 19, ["name"] = "default:steelblock"}, {["x"] = 3, ["y"] = 13, ["param1"] = 15, ["z"] = 20, ["name"] = "default:steelblock"}, {["x"] = 3, ["y"] = 13, ["param1"] = 15, ["z"] = 21, ["name"] = "default:steelblock"}, {["x"] = 3, ["y"] = 13, ["param1"] = 15, ["z"] = 22, ["name"] = "default:steelblock"}, {["x"] = 3, ["y"] = 13, ["param1"] = 15, ["z"] = 23, ["name"] = "default:steelblock"}, {["x"] = 3, ["y"] = 13, ["param1"] = 15, ["z"] = 24, ["name"] = "default:steelblock"}, {["x"] = 3, ["y"] = 13, ["param1"] = 15, ["z"] = 25, ["name"] = "default:steelblock"}, {["x"] = 3, ["y"] = 13, ["param1"] = 15, ["z"] = 26, ["name"] = "default:steelblock"}, {["x"] = 3, ["y"] = 13, ["param1"] = 14, ["z"] = 27, ["name"] = "default:steelblock"}, {["x"] = 3, ["y"] = 13, ["param1"] = 14, ["z"] = 28, ["name"] = "default:steelblock"}, {["x"] = 3, ["y"] = 13, ["param1"] = 15, ["z"] = 29, ["name"] = "default:steelblock"}, {["x"] = 3, ["y"] = 13, ["param1"] = 15, ["z"] = 30, ["name"] = "default:steelblock"}, {["x"] = 3, ["y"] = 13, ["param1"] = 15, ["z"] = 31, ["name"] = "default:steelblock"}, {["x"] = 3, ["y"] = 13, ["param1"] = 15, ["z"] = 32, ["name"] = "default:steelblock"}, {["x"] = 3, ["y"] = 13, ["param1"] = 15, ["z"] = 33, ["name"] = "default:steelblock"}, {["x"] = 3, ["y"] = 13, ["param1"] = 15, ["z"] = 34, ["name"] = "default:steelblock"}, {["x"] = 3, ["y"] = 13, ["param1"] = 15, ["z"] = 35, ["name"] = "default:steelblock"}, {["x"] = 3, ["y"] = 13, ["param1"] = 15, ["z"] = 36, ["name"] = "default:steelblock"}, {["x"] = 3, ["y"] = 13, ["param1"] = 15, ["z"] = 37, ["name"] = "default:steelblock"}, {["x"] = 3, ["y"] = 13, ["param1"] = 15, ["z"] = 38, ["name"] = "default:steelblock"}, {["x"] = 3, ["y"] = 13, ["param1"] = 15, ["z"] = 39, ["name"] = "default:steelblock"}, {["x"] = 3, ["y"] = 13, ["param1"] = 15, ["z"] = 40, ["name"] = "default:steelblock"}, {["x"] = 3, ["y"] = 13, ["param1"] = 15, ["z"] = 41, ["name"] = "default:steelblock"}, {["x"] = 3, ["y"] = 13, ["param1"] = 15, ["z"] = 42, ["name"] = "default:steelblock"}, {["x"] = 3, ["y"] = 13, ["param1"] = 14, ["z"] = 43, ["name"] = "default:steelblock"}, {["x"] = 3, ["y"] = 13, ["param1"] = 14, ["z"] = 44, ["name"] = "default:steelblock"}, {["x"] = 3, ["y"] = 13, ["param1"] = 15, ["z"] = 45, ["name"] = "default:steelblock"}, {["x"] = 3, ["y"] = 13, ["param1"] = 15, ["z"] = 46, ["name"] = "default:steelblock"}, {["x"] = 3, ["y"] = 13, ["param1"] = 15, ["z"] = 47, ["name"] = "default:steelblock"}, {["x"] = 3, ["y"] = 13, ["param1"] = 15, ["z"] = 48, ["name"] = "default:steelblock"}, {["x"] = 3, ["y"] = 13, ["param1"] = 15, ["z"] = 49, ["name"] = "default:steelblock"}, {["x"] = 3, ["y"] = 13, ["param1"] = 15, ["z"] = 50, ["name"] = "default:steelblock"}, {["x"] = 3, ["y"] = 13, ["param1"] = 15, ["z"] = 51, ["name"] = "default:steelblock"}, {["x"] = 3, ["y"] = 13, ["param1"] = 15, ["z"] = 52, ["name"] = "default:steelblock"}, {["x"] = 4, ["y"] = 0, ["param1"] = 62, ["z"] = 2, ["name"] = "stairs:stair_steelblock"}, {["x"] = 4, ["y"] = 0, ["param1"] = 15, ["z"] = 3, ["name"] = "default:steelblock"}, {["x"] = 4, ["y"] = 0, ["param1"] = 15, ["z"] = 4, ["name"] = "default:steelblock"}, {["x"] = 4, ["y"] = 0, ["param1"] = 15, ["z"] = 5, ["name"] = "default:steelblock"}, {["x"] = 4, ["y"] = 0, ["param1"] = 15, ["z"] = 6, ["name"] = "default:steelblock"}, {["x"] = 4, ["y"] = 0, ["param1"] = 15, ["z"] = 7, ["name"] = "default:steelblock"}, {["x"] = 4, ["y"] = 0, ["param1"] = 15, ["z"] = 8, ["name"] = "default:steelblock"}, {["x"] = 4, ["y"] = 0, ["param1"] = 15, ["z"] = 9, ["name"] = "default:steelblock"}, {["x"] = 4, ["y"] = 0, ["param1"] = 15, ["z"] = 10, ["name"] = "default:steelblock"}, {["x"] = 4, ["y"] = 0, ["param1"] = 15, ["z"] = 11, ["name"] = "default:steelblock"}, {["x"] = 4, ["y"] = 0, ["param1"] = 15, ["z"] = 12, ["name"] = "default:steelblock"}, {["x"] = 4, ["y"] = 0, ["param1"] = 15, ["z"] = 13, ["name"] = "default:steelblock"}, {["x"] = 4, ["y"] = 0, ["param1"] = 15, ["z"] = 14, ["name"] = "default:steelblock"}, {["x"] = 4, ["y"] = 0, ["param1"] = 15, ["z"] = 15, ["name"] = "default:steelblock"}, {["x"] = 4, ["y"] = 0, ["param1"] = 15, ["z"] = 16, ["name"] = "default:steelblock"}, {["x"] = 4, ["y"] = 0, ["param1"] = 15, ["z"] = 17, ["name"] = "default:steelblock"}, {["x"] = 4, ["y"] = 0, ["param1"] = 15, ["z"] = 18, ["name"] = "default:steelblock"}, {["x"] = 4, ["y"] = 0, ["param1"] = 15, ["z"] = 19, ["name"] = "default:steelblock"}, {["x"] = 4, ["y"] = 0, ["param1"] = 15, ["z"] = 20, ["name"] = "default:steelblock"}, {["x"] = 4, ["y"] = 0, ["param1"] = 15, ["z"] = 21, ["name"] = "default:steelblock"}, {["x"] = 4, ["y"] = 0, ["param1"] = 15, ["z"] = 22, ["name"] = "default:steelblock"}, {["x"] = 4, ["y"] = 0, ["param1"] = 15, ["z"] = 23, ["name"] = "default:steelblock"}, {["x"] = 4, ["y"] = 0, ["param1"] = 15, ["z"] = 24, ["name"] = "default:steelblock"}, {["x"] = 4, ["y"] = 0, ["param1"] = 15, ["z"] = 25, ["name"] = "default:steelblock"}, {["x"] = 4, ["y"] = 0, ["param1"] = 15, ["z"] = 26, ["name"] = "default:steelblock"}, {["x"] = 4, ["y"] = 0, ["param1"] = 15, ["z"] = 27, ["name"] = "default:steelblock"}, {["x"] = 4, ["y"] = 0, ["param1"] = 15, ["z"] = 28, ["name"] = "default:steelblock"}, {["x"] = 4, ["y"] = 0, ["param1"] = 15, ["z"] = 29, ["name"] = "default:steelblock"}, {["x"] = 4, ["y"] = 0, ["param1"] = 15, ["z"] = 30, ["name"] = "default:steelblock"}, {["x"] = 4, ["y"] = 0, ["param1"] = 15, ["z"] = 31, ["name"] = "default:steelblock"}, {["x"] = 4, ["y"] = 0, ["param1"] = 15, ["z"] = 32, ["name"] = "default:steelblock"}, {["x"] = 4, ["y"] = 0, ["param1"] = 15, ["z"] = 33, ["name"] = "default:steelblock"}, {["x"] = 4, ["y"] = 0, ["param1"] = 15, ["z"] = 34, ["name"] = "default:steelblock"}, {["x"] = 4, ["y"] = 0, ["param1"] = 15, ["z"] = 35, ["name"] = "default:steelblock"}, {["x"] = 4, ["y"] = 0, ["param1"] = 15, ["z"] = 36, ["name"] = "default:steelblock"}, {["x"] = 4, ["y"] = 0, ["param1"] = 15, ["z"] = 37, ["name"] = "default:steelblock"}, {["x"] = 4, ["y"] = 0, ["param1"] = 15, ["z"] = 38, ["name"] = "default:steelblock"}, {["x"] = 4, ["y"] = 0, ["param1"] = 15, ["z"] = 39, ["name"] = "default:steelblock"}, {["x"] = 4, ["y"] = 0, ["param1"] = 15, ["z"] = 40, ["name"] = "default:steelblock"}, {["x"] = 4, ["y"] = 0, ["param1"] = 15, ["z"] = 41, ["name"] = "default:steelblock"}, {["x"] = 4, ["y"] = 0, ["param1"] = 15, ["z"] = 42, ["name"] = "default:steelblock"}, {["x"] = 4, ["y"] = 0, ["param1"] = 15, ["z"] = 43, ["name"] = "default:steelblock"}, {["x"] = 4, ["y"] = 0, ["param1"] = 15, ["z"] = 44, ["name"] = "default:steelblock"}, {["x"] = 4, ["y"] = 0, ["param1"] = 15, ["z"] = 45, ["name"] = "default:steelblock"}, {["x"] = 4, ["y"] = 0, ["param1"] = 15, ["z"] = 46, ["name"] = "default:steelblock"}, {["x"] = 4, ["y"] = 0, ["param1"] = 15, ["z"] = 47, ["name"] = "default:steelblock"}, {["x"] = 4, ["y"] = 0, ["param1"] = 15, ["z"] = 48, ["name"] = "default:steelblock"}, {["x"] = 4, ["y"] = 0, ["param1"] = 15, ["z"] = 49, ["name"] = "default:steelblock"}, {["x"] = 4, ["y"] = 0, ["param1"] = 15, ["z"] = 50, ["name"] = "default:steelblock"}, {["x"] = 4, ["y"] = 0, ["param1"] = 15, ["z"] = 51, ["name"] = "default:steelblock"}, {["x"] = 4, ["y"] = 0, ["param1"] = 15, ["z"] = 52, ["name"] = "default:steelblock"}, {["x"] = 4, ["param2"] = 2, ["y"] = 0, ["param1"] = 14, ["z"] = 53, ["name"] = "stairs:stair_steelblock"}, {["x"] = 4, ["y"] = 1, ["param1"] = 15, ["z"] = 3, ["name"] = "default:steelblock"}, {["x"] = 4, ["y"] = 1, ["param1"] = 15, ["z"] = 17, ["name"] = "default:steelblock"}, {["x"] = 4, ["y"] = 1, ["param1"] = 15, ["z"] = 31, ["name"] = "default:steelblock"}, {["x"] = 4, ["param2"] = 2, ["y"] = 1, ["param1"] = 158, ["z"] = 32, ["name"] = "university:lobby_table"}, {["x"] = 4, ["y"] = 1, ["param1"] = 158, ["z"] = 41, ["name"] = "university:lobby_table"}, {["x"] = 4, ["y"] = 1, ["param1"] = 15, ["z"] = 42, ["name"] = "default:steelblock"}, {["x"] = 4, ["y"] = 1, ["param1"] = 15, ["z"] = 45, ["name"] = "default:steelblock"}, {["x"] = 4, ["y"] = 1, ["param1"] = 15, ["z"] = 46, ["name"] = "default:steelblock"}, {["x"] = 4, ["y"] = 1, ["param1"] = 15, ["z"] = 47, ["name"] = "default:steelblock"}, {["x"] = 4, ["y"] = 1, ["z"] = 50, ["name"] = "default:steelblock"}, {["x"] = 4, ["y"] = 1, ["param1"] = 15, ["z"] = 51, ["name"] = "default:steelblock"}, {["x"] = 4, ["y"] = 1, ["param1"] = 15, ["z"] = 52, ["name"] = "default:steelblock"}, {["x"] = 4, ["y"] = 2, ["param1"] = 15, ["z"] = 3, ["name"] = "default:steelblock"}, {["x"] = 4, ["y"] = 2, ["param1"] = 158, ["z"] = 16, ["name"] = "university:blackboard_bottom"}, {["x"] = 4, ["y"] = 2, ["param1"] = 15, ["z"] = 17, ["name"] = "default:steelblock"}, {["x"] = 4, ["y"] = 2, ["param1"] = 158, ["z"] = 30, ["name"] = "university:blackboard_bottom"}, {["x"] = 4, ["y"] = 2, ["param1"] = 15, ["z"] = 31, ["name"] = "default:steelblock"}, {["x"] = 4, ["y"] = 2, ["param1"] = 15, ["z"] = 42, ["name"] = "default:steelblock"}, {["x"] = 4, ["y"] = 2, ["param1"] = 15, ["z"] = 45, ["name"] = "default:steelblock"}, {["x"] = 4, ["y"] = 2, ["param1"] = 15, ["z"] = 46, ["name"] = "default:steelblock"}, {["x"] = 4, ["y"] = 2, ["param1"] = 15, ["z"] = 47, ["name"] = "default:steelblock"}, {["x"] = 4, ["y"] = 2, ["param1"] = 15, ["z"] = 50, ["name"] = "default:steelblock"}, {["x"] = 4, ["y"] = 2, ["param1"] = 15, ["z"] = 51, ["name"] = "default:steelblock"}, {["x"] = 4, ["y"] = 2, ["param1"] = 15, ["z"] = 52, ["name"] = "default:steelblock"}, {["x"] = 4, ["y"] = 3, ["param1"] = 15, ["z"] = 3, ["name"] = "default:steelblock"}, {["x"] = 4, ["y"] = 3, ["param1"] = 174, ["z"] = 16, ["name"] = "university:blackboard_top"}, {["x"] = 4, ["y"] = 3, ["param1"] = 15, ["z"] = 17, ["name"] = "default:steelblock"}, {["x"] = 4, ["y"] = 3, ["param1"] = 174, ["z"] = 30, ["name"] = "university:blackboard_top"}, {["x"] = 4, ["y"] = 3, ["param1"] = 15, ["z"] = 31, ["name"] = "default:steelblock"}, {["x"] = 4, ["y"] = 3, ["param1"] = 15, ["z"] = 42, ["name"] = "default:steelblock"}, {["x"] = 4, ["y"] = 3, ["param1"] = 15, ["z"] = 45, ["name"] = "default:steelblock"}, {["x"] = 4, ["y"] = 3, ["param1"] = 15, ["z"] = 46, ["name"] = "default:steelblock"}, {["x"] = 4, ["y"] = 3, ["param1"] = 15, ["z"] = 47, ["name"] = "default:steelblock"}, {["x"] = 4, ["y"] = 3, ["param1"] = 15, ["z"] = 50, ["name"] = "default:steelblock"}, {["x"] = 4, ["y"] = 3, ["param1"] = 15, ["z"] = 51, ["name"] = "default:steelblock"}, {["x"] = 4, ["y"] = 3, ["param1"] = 15, ["z"] = 52, ["name"] = "default:steelblock"}, {["x"] = 4, ["y"] = 4, ["param1"] = 15, ["z"] = 3, ["name"] = "default:steelblock"}, {["x"] = 4, ["y"] = 4, ["param1"] = 190, ["z"] = 16, ["name"] = "university:blackboard_top"}, {["x"] = 4, ["y"] = 4, ["param1"] = 15, ["z"] = 17, ["name"] = "default:steelblock"}, {["x"] = 4, ["y"] = 4, ["param1"] = 190, ["z"] = 30, ["name"] = "university:blackboard_top"}, {["x"] = 4, ["y"] = 4, ["param1"] = 15, ["z"] = 31, ["name"] = "default:steelblock"}, {["x"] = 4, ["y"] = 4, ["param1"] = 15, ["z"] = 42, ["name"] = "default:steelblock"}, {["x"] = 4, ["y"] = 4, ["param1"] = 15, ["z"] = 45, ["name"] = "default:steelblock"}, {["x"] = 4, ["y"] = 4, ["param1"] = 15, ["z"] = 46, ["name"] = "default:steelblock"}, {["x"] = 4, ["y"] = 4, ["param1"] = 15, ["z"] = 47, ["name"] = "default:steelblock"}, {["x"] = 4, ["y"] = 4, ["z"] = 50, ["name"] = "default:steelblock"}, {["x"] = 4, ["y"] = 4, ["param1"] = 15, ["z"] = 51, ["name"] = "default:steelblock"}, {["x"] = 4, ["y"] = 4, ["param1"] = 15, ["z"] = 52, ["name"] = "default:steelblock"}, {["x"] = 4, ["y"] = 5, ["param1"] = 15, ["z"] = 3, ["name"] = "default:steelblock"}, {["x"] = 4, ["y"] = 5, ["param1"] = 206, ["z"] = 16, ["name"] = "university:blackboard_top"}, {["x"] = 4, ["y"] = 5, ["param1"] = 15, ["z"] = 17, ["name"] = "default:steelblock"}, {["x"] = 4, ["y"] = 5, ["param1"] = 206, ["z"] = 30, ["name"] = "university:blackboard_top"}, {["x"] = 4, ["y"] = 5, ["param1"] = 15, ["z"] = 31, ["name"] = "default:steelblock"}, {["x"] = 4, ["y"] = 5, ["param1"] = 15, ["z"] = 42, ["name"] = "default:steelblock"}, {["x"] = 4, ["y"] = 5, ["param1"] = 15, ["z"] = 45, ["name"] = "default:steelblock"}, {["x"] = 4, ["y"] = 5, ["param1"] = 15, ["z"] = 46, ["name"] = "default:steelblock"}, {["x"] = 4, ["y"] = 5, ["param1"] = 15, ["z"] = 47, ["name"] = "default:steelblock"}, {["x"] = 4, ["y"] = 5, ["param1"] = 15, ["z"] = 50, ["name"] = "default:steelblock"}, {["x"] = 4, ["y"] = 5, ["param1"] = 15, ["z"] = 51, ["name"] = "default:steelblock"}, {["x"] = 4, ["y"] = 5, ["param1"] = 15, ["z"] = 52, ["name"] = "default:steelblock"}, {["x"] = 4, ["y"] = 6, ["param1"] = 15, ["z"] = 3, ["name"] = "default:steelblock"}, {["x"] = 4, ["param2"] = 2, ["y"] = 6, ["param1"] = 239, ["z"] = 4, ["name"] = "morelights_modern:barlight_s"}, {["x"] = 4, ["y"] = 6, ["param1"] = 239, ["z"] = 15, ["name"] = "morelights_modern:barlight_s"}, {["x"] = 4, ["y"] = 6, ["param1"] = 222, ["z"] = 16, ["name"] = "university:blackboard_top"}, {["x"] = 4, ["y"] = 6, ["param1"] = 15, ["z"] = 17, ["name"] = "default:steelblock"}, {["x"] = 4, ["param2"] = 2, ["y"] = 6, ["param1"] = 239, ["z"] = 18, ["name"] = "morelights_modern:barlight_s"}, {["x"] = 4, ["y"] = 6, ["param1"] = 239, ["z"] = 29, ["name"] = "morelights_modern:barlight_s"}, {["x"] = 4, ["y"] = 6, ["param1"] = 222, ["z"] = 30, ["name"] = "university:blackboard_top"}, {["x"] = 4, ["y"] = 6, ["param1"] = 15, ["z"] = 31, ["name"] = "default:steelblock"}, {["x"] = 4, ["param2"] = 2, ["y"] = 6, ["param1"] = 239, ["z"] = 32, ["name"] = "morelights_modern:barlight_s"}, {["x"] = 4, ["y"] = 6, ["param1"] = 239, ["z"] = 41, ["name"] = "morelights_modern:barlight_s"}, {["x"] = 4, ["y"] = 6, ["param1"] = 15, ["z"] = 42, ["name"] = "default:steelblock"}, {["x"] = 4, ["y"] = 6, ["param1"] = 15, ["z"] = 45, ["name"] = "default:steelblock"}, {["x"] = 4, ["y"] = 6, ["param1"] = 15, ["z"] = 46, ["name"] = "default:steelblock"}, {["x"] = 4, ["y"] = 6, ["param1"] = 15, ["z"] = 47, ["name"] = "default:steelblock"}, {["x"] = 4, ["y"] = 6, ["param1"] = 15, ["z"] = 50, ["name"] = "default:steelblock"}, {["x"] = 4, ["y"] = 6, ["param1"] = 15, ["z"] = 51, ["name"] = "default:steelblock"}, {["x"] = 4, ["y"] = 6, ["param1"] = 15, ["z"] = 52, ["name"] = "default:steelblock"}, {["x"] = 4, ["y"] = 7, ["param1"] = 15, ["z"] = 3, ["name"] = "default:steelblock"}, {["x"] = 4, ["y"] = 7, ["param1"] = 15, ["z"] = 17, ["name"] = "default:steelblock"}, {["x"] = 4, ["y"] = 7, ["param1"] = 15, ["z"] = 31, ["name"] = "default:steelblock"}, {["x"] = 4, ["y"] = 7, ["param1"] = 15, ["z"] = 42, ["name"] = "default:steelblock"}, {["x"] = 4, ["y"] = 7, ["param1"] = 15, ["z"] = 45, ["name"] = "default:steelblock"}, {["x"] = 4, ["y"] = 7, ["param1"] = 15, ["z"] = 46, ["name"] = "default:steelblock"}, {["x"] = 4, ["y"] = 7, ["param1"] = 15, ["z"] = 47, ["name"] = "default:steelblock"}, {["x"] = 4, ["y"] = 7, ["param1"] = 15, ["z"] = 50, ["name"] = "default:steelblock"}, {["x"] = 4, ["y"] = 7, ["param1"] = 15, ["z"] = 51, ["name"] = "default:steelblock"}, {["x"] = 4, ["y"] = 7, ["param1"] = 15, ["z"] = 52, ["name"] = "default:steelblock"}, {["x"] = 4, ["y"] = 8, ["param1"] = 15, ["z"] = 3, ["name"] = "default:steelblock"}, {["x"] = 4, ["y"] = 8, ["param1"] = 15, ["z"] = 17, ["name"] = "default:steelblock"}, {["x"] = 4, ["y"] = 8, ["param1"] = 15, ["z"] = 31, ["name"] = "default:steelblock"}, {["x"] = 4, ["y"] = 8, ["param1"] = 15, ["z"] = 42, ["name"] = "default:steelblock"}, {["x"] = 4, ["y"] = 8, ["param1"] = 15, ["z"] = 45, ["name"] = "default:steelblock"}, {["x"] = 4, ["y"] = 8, ["param1"] = 15, ["z"] = 46, ["name"] = "default:steelblock"}, {["x"] = 4, ["y"] = 8, ["param1"] = 15, ["z"] = 47, ["name"] = "default:steelblock"}, {["x"] = 4, ["y"] = 8, ["param1"] = 15, ["z"] = 50, ["name"] = "default:steelblock"}, {["x"] = 4, ["y"] = 8, ["param1"] = 15, ["z"] = 51, ["name"] = "default:steelblock"}, {["x"] = 4, ["y"] = 8, ["param1"] = 15, ["z"] = 52, ["name"] = "default:steelblock"}, {["x"] = 4, ["y"] = 9, ["param1"] = 15, ["z"] = 3, ["name"] = "default:steelblock"}, {["x"] = 4, ["y"] = 9, ["param1"] = 15, ["z"] = 17, ["name"] = "default:steelblock"},